Workbook

Sheet Sessions
D1: Session 1 | K1: Session 2 | R1: Session 3 | Y1: Session 4 | AF1: Session 5 | AM1: Session 6 | AT1: Session 7 | BA1: Session 8 | BH1: Session 9 | BO1: Session 10 | BV1: Session 11 | CC1: Session 12
A2: Routine | B2: Exercise | C2: Notes | D2: Date | E2: S1 Wt | F2: S1 Reps | G2: S2 Wt | H2: S2 Reps | I2: S3 Wt | J2: S3 Reps | K2: Date | L2: S1 Wt | M2: S1 Reps | N2: S2 Wt | O2: S2 Reps | P2: S3 Wt | Q2: S3 Reps | R2: Date | S2: S1 Wt | T2: S1 Reps | U2: S2 Wt | V2: S2 Reps | W2: S3 Wt | X2: S3 Reps | Y2: Date | Z2: S1 Wt | AA2: S1 Reps | AB2: S2 Wt | AC2: S2 Reps | AD2: S3 Wt | AE2: S3 Reps | AF2: Date | AG2: S1 Wt | AH2: S1 Reps | AI2: S2 Wt | AJ2: S2 Reps | AK2: S3 Wt | AL2: S3 Reps | AM2: Date | AN2: S1 Wt | AO2: S1 Reps | AP2: S2 Wt | AQ2: S2 Reps | AR2: S3 Wt | AS2: S3 Reps | AT2: Date | AU2: S1 Wt | AV2: S1 Reps | AW2: S2 Wt | AX2: S2 Reps | AY2: S3 Wt | AZ2: S3 Reps | BA2: Date | BB2: S1 Wt | BC2: S1 Reps | BD2: S2 Wt | BE2: S2 Reps | BF2: S3 Wt | BG2: S3 Reps | BH2: Date | BI2: S1 Wt | BJ2: S1 Reps | BK2: S2 Wt | BL2: S2 Reps | BM2: S3 Wt | BN2: S3 Reps | BO2: Date | BP2: S1 Wt | BQ2: S1 Reps | BR2: S2 Wt | BS2: S2 Reps | BT2: S3 Wt | BU2: S3 Reps | BV2: Date | BW2: S1 Wt | BX2: S1 Reps | BY2: S2 Wt | BZ2: S2 Reps | CA2: S3 Wt | CB2: S3 Reps | CC2: Date | CD2: S1 Wt | CE2: S1 Reps | CF2: S2 Wt | CG2: S2 Reps | CH2: S3 Wt | CI2: S3 Reps
A3: Lower Body - 1 | B3: Barbell Squat | E3: 30
B4: Lying Hamstring Curl | E4: 35
B5: Low Box Step Up | E5: 24
B6: Goblet Squat | E6: 12
B7: Pallof Press | C7: 3 sets, 10 per side | E7: N/A
A9: Lower Body - 2 | B9: Barbell Romaniam Deadlift | E9: 30
B10: Dumbbell Bulgarian Split Squat | E10: 5
B11: Single Leg Lying Hamstring Curl | E11: 15
B12: Leg Extension | E12: 35
B13: Banded Leg Raise (Dead Bug) | C13: 3 sets, 10 per side. | E13: N/A
A15: Upper Body - 1 | B15: Flat Dumbbell Press | C15: Superset with Lat Pulldown | E15: 15
B16: Lat Pull Down | E16: 45
B17: Cable Chest Fly | C17: Superset with Seated Row | E17: 15
B18: Seated Row | E18: 45
B19: Dumbbell Upright Row | E19: 10
B20: Dumbbel Side Raises | E20: 5
B21: Rope Tricep Extensions | C21: Max Effort, x 2 | E21: 20
B22: Incline Dumbbell Bicep Curl | C22: Max Effort, x 2 | E22: 8
A24: Upper Body - 2 | B24: Wide Grip Lat Pulldown | E24: 50
B25: Close Grip Barbell Bench Press | E25: 20
B26: T-Bar Row | C26: superset with overhead press | E26: 30
B27: Seated Dumbbell Overhead Press | E27: 12.5
B28: Dumbbell Hammer Curls | C28: Max Effort, x2 | E28: 9
B29: Overhead Tricep Extension | C29: Max Effort, x2 | E29: 5
A31: Lower Body 1b | B31: Pendulum Squat | E31: 5
B32: Split Leg Press | E32: 30
B33: Lying Hamstring Curl | E33: 35
B34: Leg Press | E34: 80
B35: Hanging Leg Raises | E35: N/A
B36: Single Leg Slant Board Calf Raise | E36: N/A
A38: Lower Body 2b | B38: Barbell Deadlift | E38: 30
B39: Lying Single Leg Hamgstring Curl | E39: 20
B40: Single Leg Press | E40: 30
B41: Calf Raises | E41: 25
B42: Ab Wheel Rollout | E42: N/A
A44: Upper Body 1b | B44: Incline Barbell Press | E44: 15
B45: Flat Dumbell Press | E45: 12.5
B46: Cable Chest Fly | E46: 15
...

Sheet Personal Best
A1: Routine | B1: Exercise | C1: Best Weight | D1: Reps | E1: Date Achieved
A2: Lower Body - 1 | B2: =Sessions!B3 -> Barbell Squat | C2: =IF(MAX(_PB_calc!B2:AK2)=0,"",INDEX(_PB_calc!B2:AK2,MATCH(MAX(_PB_calc!DF2:EO2),_PB_calc!DF2:EO2,0))) -> 30 | D2: =IF(MAX(_PB_calc!B2:AK2)=0,"",INDEX(_PB_calc!AL2:BU2,MATCH(MAX(_PB_calc!DF2:EO2),_PB_calc!DF2:EO2,0))) -> 0 | E2: =IF(MAX(_PB_calc!B2:AK2)=0,"",INDEX(_PB_calc!BV2:DE2,MATCH(MAX(_PB_calc!DF2:EO2),_PB_calc!DF2:EO2,0))) -> 0
B3: =Sessions!B4 -> Lying Hamstring Curl | C3: =IF(MAX(_PB_calc!B3:AK3)=0,"",INDEX(_PB_calc!B3:AK3,MATCH(MAX(_PB_calc!DF3:EO3),_PB_calc!DF3:EO3,0))) -> 35 | D3: =IF(MAX(_PB_calc!B3:AK3)=0,"",INDEX(_PB_calc!AL3:BU3,MATCH(MAX(_PB_calc!DF3:EO3),_PB_calc!DF3:EO3,0))) -> 0 | E3: =IF(MAX(_PB_calc!B3:AK3)=0,"",INDEX(_PB_calc!BV3:DE3,MATCH(MAX(_PB_calc!DF3:EO3),_PB_calc!DF3:EO3,0))) -> 0
B4: =Sessions!B5 -> Low Box Step Up | C4: =IF(MAX(_PB_calc!B4:AK4)=0,"",INDEX(_PB_calc!B4:AK4,MATCH(MAX(_PB_calc!DF4:EO4),_PB_calc!DF4:EO4,0))) -> 24 | D4: =IF(MAX(_PB_calc!B4:AK4)=0,"",INDEX(_PB_calc!AL4:BU4,MATCH(MAX(_PB_calc!DF4:EO4),_PB_calc!DF4:EO4,0))) -> 0 | E4: =IF(MAX(_PB_calc!B4:AK4)=0,"",INDEX(_PB_calc!BV4:DE4,MATCH(MAX(_PB_calc!DF4:EO4),_PB_calc!DF4:EO4,0))) -> 0
B5: =Sessions!B6 -> Goblet Squat | C5: =IF(MAX(_PB_calc!B5:AK5)=0,"",INDEX(_PB_calc!B5:AK5,MATCH(MAX(_PB_calc!DF5:EO5),_PB_calc!DF5:EO5,0))) -> 12 | D5: =IF(MAX(_PB_calc!B5:AK5)=0,"",INDEX(_PB_calc!AL5:BU5,MATCH(MAX(_PB_calc!DF5:EO5),_PB_calc!DF5:EO5,0))) -> 0 | E5: =IF(MAX(_PB_calc!B5:AK5)=0,"",INDEX(_PB_calc!BV5:DE5,MATCH(MAX(_PB_calc!DF5:EO5),_PB_calc!DF5:EO5,0))) -> 0
B6: =Sessions!B7 -> Pallof Press | C6: =IF(MAX(_PB_calc!B6:AK6)=0,"",INDEX(_PB_calc!B6:AK6,MATCH(MAX(_PB_calc!DF6:EO6),_PB_calc!DF6:EO6,0))) | D6: =IF(MAX(_PB_calc!B6:AK6)=0,"",INDEX(_PB_calc!AL6:BU6,MATCH(MAX(_PB_calc!DF6:EO6),_PB_calc!DF6:EO6,0))) | E6: =IF(MAX(_PB_calc!B6:AK6)=0,"",INDEX(_PB_calc!BV6:DE6,MATCH(MAX(_PB_calc!DF6:EO6),_PB_calc!DF6:EO6,0)))
A7: Lower Body - 2 | B7: =Sessions!B9 -> Barbell Romaniam Deadlift | C7: =IF(MAX(_PB_calc!B7:AK7)=0,"",INDEX(_PB_calc!B7:AK7,MATCH(MAX(_PB_calc!DF7:EO7),_PB_calc!DF7:EO7,0))) -> 30 | D7: =IF(MAX(_PB_calc!B7:AK7)=0,"",INDEX(_PB_calc!AL7:BU7,MATCH(MAX(_PB_calc!DF7:EO7),_PB_calc!DF7:EO7,0))) -> 0 | E7: =IF(MAX(_PB_calc!B7:AK7)=0,"",INDEX(_PB_calc!BV7:DE7,MATCH(MAX(_PB_calc!DF7:EO7),_PB_calc!DF7:EO7,0))) -> 0
B8: =Sessions!B10 -> Dumbbell Bulgarian Split Squat | C8: =IF(MAX(_PB_calc!B8:AK8)=0,"",INDEX(_PB_calc!B8:AK8,MATCH(MAX(_PB_calc!DF8:EO8),_PB_calc!DF8:EO8,0))) -> 5 | D8: =IF(MAX(_PB_calc!B8:AK8)=0,"",INDEX(_PB_calc!AL8:BU8,MATCH(MAX(_PB_calc!DF8:EO8),_PB_calc!DF8:EO8,0))) -> 0 | E8: =IF(MAX(_PB_calc!B8:AK8)=0,"",INDEX(_PB_calc!BV8:DE8,MATCH(MAX(_PB_calc!DF8:EO8),_PB_calc!DF8:EO8,0))) -> 0
B9: =Sessions!B11 -> Single Leg Lying Hamstring Curl | C9: =IF(MAX(_PB_calc!B9:AK9)=0,"",INDEX(_PB_calc!B9:AK9,MATCH(MAX(_PB_calc!DF9:EO9),_PB_calc!DF9:EO9,0))) -> 15 | D9: =IF(MAX(_PB_calc!B9:AK9)=0,"",INDEX(_PB_calc!AL9:BU9,MATCH(MAX(_PB_calc!DF9:EO9),_PB_calc!DF9:EO9,0))) -> 0 | E9: =IF(MAX(_PB_calc!B9:AK9)=0,"",INDEX(_PB_calc!BV9:DE9,MATCH(MAX(_PB_calc!DF9:EO9),_PB_calc!DF9:EO9,0))) -> 0
B10: =Sessions!B12 -> Leg Extension | C10: =IF(MAX(_PB_calc!B10:AK10)=0,"",INDEX(_PB_calc!B10:AK10,MATCH(MAX(_PB_calc!DF10:EO10),_PB_calc!DF10:EO10,0))) -> 35 | D10: =IF(MAX(_PB_calc!B10:AK10)=0,"",INDEX(_PB_calc!AL10:BU10,MATCH(MAX(_PB_calc!DF10:EO10),_PB_calc!DF10:EO10,0))) -> 0 | E10: =IF(MAX(_PB_calc!B10:AK10)=0,"",INDEX(_PB_calc!BV10:DE10,MATCH(MAX(_PB_calc!DF10:EO10),_PB_calc!DF10:EO10,0))) -> 0
B11: =Sessions!B13 -> Banded Leg Raise (Dead Bug) | C11: =IF(MAX(_PB_calc!B11:AK11)=0,"",INDEX(_PB_calc!B11:AK11,MATCH(MAX(_PB_calc!DF11:EO11),_PB_calc!DF11:EO11,0))) | D11: =IF(MAX(_PB_calc!B11:AK11)=0,"",INDEX(_PB_calc!AL11:BU11,MATCH(MAX(_PB_calc!DF11:EO11),_PB_calc!DF11:EO11,0))) | E11: =IF(MAX(_PB_calc!B11:AK11)=0,"",INDEX(_PB_calc!BV11:DE11,MATCH(MAX(_PB_calc!DF11:EO11),_PB_calc!DF11:EO11,0)))
A12: Upper Body - 1 | B12: =Sessions!B15 -> Flat Dumbbell Press | C12: =IF(MAX(_PB_calc!B12:AK12)=0,"",INDEX(_PB_calc!B12:AK12,MATCH(MAX(_PB_calc!DF12:EO12),_PB_calc!DF12:EO12,0))) -> 15 | D12: =IF(MAX(_PB_calc!B12:AK12)=0,"",INDEX(_PB_calc!AL12:BU12,MATCH(MAX(_PB_calc!DF12:EO12),_PB_calc!DF12:EO12,0))) -> 0 | E12: =IF(MAX(_PB_calc!B12:AK12)=0,"",INDEX(_PB_calc!BV12:DE12,MATCH(MAX(_PB_calc!DF12:EO12),_PB_calc!DF12:EO12,0))) -> 0
B13: =Sessions!B16 -> Lat Pull Down | C13: =IF(MAX(_PB_calc!B13:AK13)=0,"",INDEX(_PB_calc!B13:AK13,MATCH(MAX(_PB_calc!DF13:EO13),_PB_calc!DF13:EO13,0))) -> 45 | D13: =IF(MAX(_PB_calc!B13:AK13)=0,"",INDEX(_PB_calc!AL13:BU13,MATCH(MAX(_PB_calc!DF13:EO13),_PB_calc!DF13:EO13,0))) -> 0 | E13: =IF(MAX(_PB_calc!B13:AK13)=0,"",INDEX(_PB_calc!BV13:DE13,MATCH(MAX(_PB_calc!DF13:EO13),_PB_calc!DF13:EO13,0))) -> 0
B14: =Sessions!B17 -> Cable Chest Fly | C14: =IF(MAX(_PB_calc!B14:AK14)=0,"",INDEX(_PB_calc!B14:AK14,MATCH(MAX(_PB_calc!DF14:EO14),_PB_calc!DF14:EO14,0))) -> 15 | D14: =IF(MAX(_PB_calc!B14:AK14)=0,"",INDEX(_PB_calc!AL14:BU14,MATCH(MAX(_PB_calc!DF14:EO14),_PB_calc!DF14:EO14,0))) -> 0 | E14: =IF(MAX(_PB_calc!B14:AK14)=0,"",INDEX(_PB_calc!BV14:DE14,MATCH(MAX(_PB_calc!DF14:EO14),_PB_calc!DF14:EO14,0))) -> 0
B15: =Sessions!B18 -> Seated Row | C15: =IF(MAX(_PB_calc!B15:AK15)=0,"",INDEX(_PB_calc!B15:AK15,MATCH(MAX(_PB_calc!DF15:EO15),_PB_calc!DF15:EO15,0))) -> 45 | D15: =IF(MAX(_PB_calc!B15:AK15)=0,"",INDEX(_PB_calc!AL15:BU15,MATCH(MAX(_PB_calc!DF15:EO15),_PB_calc!DF15:EO15,0))) -> 0 | E15: =IF(MAX(_PB_calc!B15:AK15)=0,"",INDEX(_PB_calc!BV15:DE15,MATCH(MAX(_PB_calc!DF15:EO15),_PB_calc!DF15:EO15,0))) -> 0
B16: =Sessions!B19 -> Dumbbell Upright Row | C16: =IF(MAX(_PB_calc!B16:AK16)=0,"",INDEX(_PB_calc!B16:AK16,MATCH(MAX(_PB_calc!DF16:EO16),_PB_calc!DF16:EO16,0))) -> 10 | D16: =IF(MAX(_PB_calc!B16:AK16)=0,"",INDEX(_PB_calc!AL16:BU16,MATCH(MAX(_PB_calc!DF16:EO16),_PB_calc!DF16:EO16,0))) -> 0 | E16: =IF(MAX(_PB_calc!B16:AK16)=0,"",INDEX(_PB_calc!BV16:DE16,MATCH(MAX(_PB_calc!DF16:EO16),_PB_calc!DF16:EO16,0))) -> 0
B17: =Sessions!B20 -> Dumbbel Side Raises | C17: =IF(MAX(_PB_calc!B17:AK17)=0,"",INDEX(_PB_calc!B17:AK17,MATCH(MAX(_PB_calc!DF17:EO17),_PB_calc!DF17:EO17,0))) -> 5 | D17: =IF(MAX(_PB_calc!B17:AK17)=0,"",INDEX(_PB_calc!AL17:BU17,MATCH(MAX(_PB_calc!DF17:EO17),_PB_calc!DF17:EO17,0))) -> 0 | E17: =IF(MAX(_PB_calc!B17:AK17)=0,"",INDEX(_PB_calc!BV17:DE17,MATCH(MAX(_PB_calc!DF17:EO17),_PB_calc!DF17:EO17,0))) -> 0
B18: =Sessions!B21 -> Rope Tricep Extensions | C18: =IF(MAX(_PB_calc!B18:AK18)=0,"",INDEX(_PB_calc!B18:AK18,MATCH(MAX(_PB_calc!DF18:EO18),_PB_calc!DF18:EO18,0))) -> 20 | D18: =IF(MAX(_PB_calc!B18:AK18)=0,"",INDEX(_PB_calc!AL18:BU18,MATCH(MAX(_PB_calc!DF18:EO18),_PB_calc!DF18:EO18,0))) -> 0 | E18: =IF(MAX(_PB_calc!B18:AK18)=0,"",INDEX(_PB_calc!BV18:DE18,MATCH(MAX(_PB_calc!DF18:EO18),_PB_calc!DF18:EO18,0))) -> 0
B19: =Sessions!B22 -> Incline Dumbbell Bicep Curl | C19: =IF(MAX(_PB_calc!B19:AK19)=0,"",INDEX(_PB_calc!B19:AK19,MATCH(MAX(_PB_calc!DF19:EO19),_PB_calc!DF19:EO19,0))) -> 8 | D19: =IF(MAX(_PB_calc!B19:AK19)=0,"",INDEX(_PB_calc!AL19:BU19,MATCH(MAX(_PB_calc!DF19:EO19),_PB_calc!DF19:EO19,0))) -> 0 | E19: =IF(MAX(_PB_calc!B19:AK19)=0,"",INDEX(_PB_calc!BV19:DE19,MATCH(MAX(_PB_calc!DF19:EO19),_PB_calc!DF19:EO19,0))) -> 0
A20: Upper Body - 2 | B20: =Sessions!B24 -> Wide Grip Lat Pulldown | C20: =IF(MAX(_PB_calc!B20:AK20)=0,"",INDEX(_PB_calc!B20:AK20,MATCH(MAX(_PB_calc!DF20:EO20),_PB_calc!DF20:EO20,0))) -> 50 | D20: =IF(MAX(_PB_calc!B20:AK20)=0,"",INDEX(_PB_calc!AL20:BU20,MATCH(MAX(_PB_calc!DF20:EO20),_PB_calc!DF20:EO20,0))) -> 0 | E20: =IF(MAX(_PB_calc!B20:AK20)=0,"",INDEX(_PB_calc!BV20:DE20,MATCH(MAX(_PB_calc!DF20:EO20),_PB_calc!DF20:EO20,0))) -> 0
B21: =Sessions!B25 -> Close Grip Barbell Bench Press | C21: =IF(MAX(_PB_calc!B21:AK21)=0,"",INDEX(_PB_calc!B21:AK21,MATCH(MAX(_PB_calc!DF21:EO21),_PB_calc!DF21:EO21,0))) -> 20 | D21: =IF(MAX(_PB_calc!B21:AK21)=0,"",INDEX(_PB_calc!AL21:BU21,MATCH(MAX(_PB_calc!DF21:EO21),_PB_calc!DF21:EO21,0))) -> 0 | E21: =IF(MAX(_PB_calc!B21:AK21)=0,"",INDEX(_PB_calc!BV21:DE21,MATCH(MAX(_PB_calc!DF21:EO21),_PB_calc!DF21:EO21,0))) -> 0
B22: =Sessions!B26 -> T-Bar Row | C22: =IF(MAX(_PB_calc!B22:AK22)=0,"",INDEX(_PB_calc!B22:AK22,MATCH(MAX(_PB_calc!DF22:EO22),_PB_calc!DF22:EO22,0))) -> 30 | D22: =IF(MAX(_PB_calc!B22:AK22)=0,"",INDEX(_PB_calc!AL22:BU22,MATCH(MAX(_PB_calc!DF22:EO22),_PB_calc!DF22:EO22,0))) -> 0 | E22: =IF(MAX(_PB_calc!B22:AK22)=0,"",INDEX(_PB_calc!BV22:DE22,MATCH(MAX(_PB_calc!DF22:EO22),_PB_calc!DF22:EO22,0))) -> 0
B23: =Sessions!B27 -> Seated Dumbbell Overhead Press | C23: =IF(MAX(_PB_calc!B23:AK23)=0,"",INDEX(_PB_calc!B23:AK23,MATCH(MAX(_PB_calc!DF23:EO23),_PB_calc!DF23:EO23,0))) -> 12.5 | D23: =IF(MAX(_PB_calc!B23:AK23)=0,"",INDEX(_PB_calc!AL23:BU23,MATCH(MAX(_PB_calc!DF23:EO23),_PB_calc!DF23:EO23,0))) -> 0 | E23: =IF(MAX(_PB_calc!B23:AK23)=0,"",INDEX(_PB_calc!BV23:DE23,MATCH(MAX(_PB_calc!DF23:EO23),_PB_calc!DF23:EO23,0))) -> 0
B24: =Sessions!B28 -> Dumbbell Hammer Curls | C24: =IF(MAX(_PB_calc!B24:AK24)=0,"",INDEX(_PB_calc!B24:AK24,MATCH(MAX(_PB_calc!DF24:EO24),_PB_calc!DF24:EO24,0))) -> 9 | D24: =IF(MAX(_PB_calc!B24:AK24)=0,"",INDEX(_PB_calc!AL24:BU24,MATCH(MAX(_PB_calc!DF24:EO24),_PB_calc!DF24:EO24,0))) -> 0 | E24: =IF(MAX(_PB_calc!B24:AK24)=0,"",INDEX(_PB_calc!BV24:DE24,MATCH(MAX(_PB_calc!DF24:EO24),_PB_calc!DF24:EO24,0))) -> 0
B25: =Sessions!B29 -> Overhead Tricep Extension | C25: =IF(MAX(_PB_calc!B25:AK25)=0,"",INDEX(_PB_calc!B25:AK25,MATCH(MAX(_PB_calc!DF25:EO25),_PB_calc!DF25:EO25,0))) -> 5 | D25: =IF(MAX(_PB_calc!B25:AK25)=0,"",INDEX(_PB_calc!AL25:BU25,MATCH(MAX(_PB_calc!DF25:EO25),_PB_calc!DF25:EO25,0))) -> 0 | E25: =IF(MAX(_PB_calc!B25:AK25)=0,"",INDEX(_PB_calc!BV25:DE25,MATCH(MAX(_PB_calc!DF25:EO25),_PB_calc!DF25:EO25,0))) -> 0
A26: Lower Body 1b | B26: =Sessions!B31 -> Pendulum Squat | C26: =IF(MAX(_PB_calc!B26:AK26)=0,"",INDEX(_PB_calc!B26:AK26,MATCH(MAX(_PB_calc!DF26:EO26),_PB_calc!DF26:EO26,0))) -> 5 | D26: =IF(MAX(_PB_calc!B26:AK26)=0,"",INDEX(_PB_calc!AL26:BU26,MATCH(MAX(_PB_calc!DF26:EO26),_PB_calc!DF26:EO26,0))) -> 0 | E26: =IF(MAX(_PB_calc!B26:AK26)=0,"",INDEX(_PB_calc!BV26:DE26,MATCH(MAX(_PB_calc!DF26:EO26),_PB_calc!DF26:EO26,0))) -> 0
B27: =Sessions!B32 -> Split Leg Press | C27: =IF(MAX(_PB_calc!B27:AK27)=0,"",INDEX(_PB_calc!B27:AK27,MATCH(MAX(_PB_calc!DF27:EO27),_PB_calc!DF27:EO27,0))) -> 30 | D27: =IF(MAX(_PB_calc!B27:AK27)=0,"",INDEX(_PB_calc!AL27:BU27,MATCH(MAX(_PB_calc!DF27:EO27),_PB_calc!DF27:EO27,0))) -> 0 | E27: =IF(MAX(_PB_calc!B27:AK27)=0,"",INDEX(_PB_calc!BV27:DE27,MATCH(MAX(_PB_calc!DF27:EO27),_PB_calc!DF27:EO27,0))) -> 0
B28: =Sessions!B33 -> Lying Hamstring Curl | C28: =IF(MAX(_PB_calc!B28:AK28)=0,"",INDEX(_PB_calc!B28:AK28,MATCH(MAX(_PB_calc!DF28:EO28),_PB_calc!DF28:EO28,0))) -> 35 | D28: =IF(MAX(_PB_calc!B28:AK28)=0,"",INDEX(_PB_calc!AL28:BU28,MATCH(MAX(_PB_calc!DF28:EO28),_PB_calc!DF28:EO28,0))) -> 0 | E28: =IF(MAX(_PB_calc!B28:AK28)=0,"",INDEX(_PB_calc!BV28:DE28,MATCH(MAX(_PB_calc!DF28:EO28),_PB_calc!DF28:EO28,0))) -> 0
B29: =Sessions!B34 -> Leg Press | C29: =IF(MAX(_PB_calc!B29:AK29)=0,"",INDEX(_PB_calc!B29:AK29,MATCH(MAX(_PB_calc!DF29:EO29),_PB_calc!DF29:EO29,0))) -> 80 | D29: =IF(MAX(_PB_calc!B29:AK29)=0,"",INDEX(_PB_calc!AL29:BU29,MATCH(MAX(_PB_calc!DF29:EO29),_PB_calc!DF29:EO29,0))) -> 0 | E29: =IF(MAX(_PB_calc!B29:AK29)=0,"",INDEX(_PB_calc!BV29:DE29,MATCH(MAX(_PB_calc!DF29:EO29),_PB_calc!DF29:EO29,0))) -> 0
B30: =Sessions!B35 -> Hanging Leg Raises | C30: =IF(MAX(_PB_calc!B30:AK30)=0,"",INDEX(_PB_calc!B30:AK30,MATCH(MAX(_PB_calc!DF30:EO30),_PB_calc!DF30:EO30,0))) | D30: =IF(MAX(_PB_calc!B30:AK30)=0,"",INDEX(_PB_calc!AL30:BU30,MATCH(MAX(_PB_calc!DF30:EO30),_PB_calc!DF30:EO30,0))) | E30: =IF(MAX(_PB_calc!B30:AK30)=0,"",INDEX(_PB_calc!BV30:DE30,MATCH(MAX(_PB_calc!DF30:EO30),_PB_calc!DF30:EO30,0)))
B31: =Sessions!B36 -> Single Leg Slant Board Calf Raise | C31: =IF(MAX(_PB_calc!B31:AK31)=0,"",INDEX(_PB_calc!B31:AK31,MATCH(MAX(_PB_calc!DF31:EO31),_PB_calc!DF31:EO31,0))) | D31: =IF(MAX(_PB_calc!B31:AK31)=0,"",INDEX(_PB_calc!AL31:BU31,MATCH(MAX(_PB_calc!DF31:EO31),_PB_calc!DF31:EO31,0))) | E31: =IF(MAX(_PB_calc!B31:AK31)=0,"",INDEX(_PB_calc!BV31:DE31,MATCH(MAX(_PB_calc!DF31:EO31),_PB_calc!DF31:EO31,0)))
A32: Lower Body 2b | B32: =Sessions!B38 -> Barbell Deadlift | C32: =IF(MAX(_PB_calc!B32:AK32)=0,"",INDEX(_PB_calc!B32:AK32,MATCH(MAX(_PB_calc!DF32:EO32),_PB_calc!DF32:EO32,0))) -> 30 | D32: =IF(MAX(_PB_calc!B32:AK32)=0,"",INDEX(_PB_calc!AL32:BU32,MATCH(MAX(_PB_calc!DF32:EO32),_PB_calc!DF32:EO32,0))) -> 0 | E32: =IF(MAX(_PB_calc!B32:AK32)=0,"",INDEX(_PB_calc!BV32:DE32,MATCH(MAX(_PB_calc!DF32:EO32),_PB_calc!DF32:EO32,0))) -> 0
B33: =Sessions!B39 -> Lying Single Leg Hamgstring Curl | C33: =IF(MAX(_PB_calc!B33:AK33)=0,"",INDEX(_PB_calc!B33:AK33,MATCH(MAX(_PB_calc!DF33:EO33),_PB_calc!DF33:EO33,0))) -> 20 | D33: =IF(MAX(_PB_calc!B33:AK33)=0,"",INDEX(_PB_calc!AL33:BU33,MATCH(MAX(_PB_calc!DF33:EO33),_PB_calc!DF33:EO33,0))) -> 0 | E33: =IF(MAX(_PB_calc!B33:AK33)=0,"",INDEX(_PB_calc!BV33:DE33,MATCH(MAX(_PB_calc!DF33:EO33),_PB_calc!DF33:EO33,0))) -> 0
B34: =Sessions!B40 -> Single Leg Press | C34: =IF(MAX(_PB_calc!B34:AK34)=0,"",INDEX(_PB_calc!B34:AK34,MATCH(MAX(_PB_calc!DF34:EO34),_PB_calc!DF34:EO34,0))) -> 30 | D34: =IF(MAX(_PB_calc!B34:AK34)=0,"",INDEX(_PB_calc!AL34:BU34,MATCH(MAX(_PB_calc!DF34:EO34),_PB_calc!DF34:EO34,0))) -> 0 | E34: =IF(MAX(_PB_calc!B34:AK34)=0,"",INDEX(_PB_calc!BV34:DE34,MATCH(MAX(_PB_calc!DF34:EO34),_PB_calc!DF34:EO34,0))) -> 0
B35: =Sessions!B41 -> Calf Raises | C35: =IF(MAX(_PB_calc!B35:AK35)=0,"",INDEX(_PB_calc!B35:AK35,MATCH(MAX(_PB_calc!DF35:EO35),_PB_calc!DF35:EO35,0))) -> 25 | D35: =IF(MAX(_PB_calc!B35:AK35)=0,"",INDEX(_PB_calc!AL35:BU35,MATCH(MAX(_PB_calc!DF35:EO35),_PB_calc!DF35:EO35,0))) -> 0 | E35: =IF(MAX(_PB_calc!B35:AK35)=0,"",INDEX(_PB_calc!BV35:DE35,MATCH(MAX(_PB_calc!DF35:EO35),_PB_calc!DF35:EO35,0))) -> 0
B36: =Sessions!B42 -> Ab Wheel Rollout | C36: =IF(MAX(_PB_calc!B36:AK36)=0,"",INDEX(_PB_calc!B36:AK36,MATCH(MAX(_PB_calc!DF36:EO36),_PB_calc!DF36:EO36,0))) | D36: =IF(MAX(_PB_calc!B36:AK36)=0,"",INDEX(_PB_calc!AL36:BU36,MATCH(MAX(_PB_calc!DF36:EO36),_PB_calc!DF36:EO36,0))) | E36: =IF(MAX(_PB_calc!B36:AK36)=0,"",INDEX(_PB_calc!BV36:DE36,MATCH(MAX(_PB_calc!DF36:EO36),_PB_calc!DF36:EO36,0)))
A37: Upper Body 1b | B37: =Sessions!B44 -> Incline Barbell Press | C37: =IF(MAX(_PB_calc!B37:AK37)=0,"",INDEX(_PB_calc!B37:AK37,MATCH(MAX(_PB_calc!DF37:EO37),_PB_calc!DF37:EO37,0))) -> 15 | D37: =IF(MAX(_PB_calc!B37:AK37)=0,"",INDEX(_PB_calc!AL37:BU37,MATCH(MAX(_PB_calc!DF37:EO37),_PB_calc!DF37:EO37,0))) -> 0 | E37: =IF(MAX(_PB_calc!B37:AK37)=0,"",INDEX(_PB_calc!BV37:DE37,MATCH(MAX(_PB_calc!DF37:EO37),_PB_calc!DF37:EO37,0))) -> 0
B38: =Sessions!B45 -> Flat Dumbell Press | C38: =IF(MAX(_PB_calc!B38:AK38)=0,"",INDEX(_PB_calc!B38:AK38,MATCH(MAX(_PB_calc!DF38:EO38),_PB_calc!DF38:EO38,0))) -> 12.5 | D38: =IF(MAX(_PB_calc!B38:AK38)=0,"",INDEX(_PB_calc!AL38:BU38,MATCH(MAX(_PB_calc!DF38:EO38),_PB_calc!DF38:EO38,0))) -> 0 | E38: =IF(MAX(_PB_calc!B38:AK38)=0,"",INDEX(_PB_calc!BV38:DE38,MATCH(MAX(_PB_calc!DF38:EO38),_PB_calc!DF38:EO38,0))) -> 0
B39: =Sessions!B46 -> Cable Chest Fly | C39: =IF(MAX(_PB_calc!B39:AK39)=0,"",INDEX(_PB_calc!B39:AK39,MATCH(MAX(_PB_calc!DF39:EO39),_PB_calc!DF39:EO39,0))) -> 15 | D39: =IF(MAX(_PB_calc!B39:AK39)=0,"",INDEX(_PB_calc!AL39:BU39,MATCH(MAX(_PB_calc!DF39:EO39),_PB_calc!DF39:EO39,0))) -> 0 | E39: =IF(MAX(_PB_calc!B39:AK39)=0,"",INDEX(_PB_calc!BV39:DE39,MATCH(MAX(_PB_calc!DF39:EO39),_PB_calc!DF39:EO39,0))) -> 0
B40: =Sessions!B47 -> Bench Pull | C40: =IF(MAX(_PB_calc!B40:AK40)=0,"",INDEX(_PB_calc!B40:AK40,MATCH(MAX(_PB_calc!DF40:EO40),_PB_calc!DF40:EO40,0))) -> 50 | D40: =IF(MAX(_PB_calc!B40:AK40)=0,"",INDEX(_PB_calc!AL40:BU40,MATCH(MAX(_PB_calc!DF40:EO40),_PB_calc!DF40:EO40,0))) -> 0 | E40: =IF(MAX(_PB_calc!B40:AK40)=0,"",INDEX(_PB_calc!BV40:DE40,MATCH(MAX(_PB_calc!DF40:EO40),_PB_calc!DF40:EO40,0))) -> 0
...

Sheet _PB_calc
A2: =Sessions!B3 -> Barbell Squat | B2: =IFERROR(N(Sessions!E3),0) -> 30 | C2: =IFERROR(N(Sessions!G3),0) -> 0 | D2: =IFERROR(N(Sessions!I3),0) -> 0 | E2: =IFERROR(N(Sessions!L3),0) -> 0 | F2: =IFERROR(N(Sessions!N3),0) -> 0 | G2: =IFERROR(N(Sessions!P3),0) -> 0 | H2: =IFERROR(N(Sessions!S3),0) -> 0 | I2: =IFERROR(N(Sessions!U3),0) -> 0 | J2: =IFERROR(N(Sessions!W3),0) -> 0 | K2: =IFERROR(N(Sessions!Z3),0) -> 0 | L2: =IFERROR(N(Sessions!AB3),0) -> 0 | M2: =IFERROR(N(Sessions!AD3),0) -> 0 | N2: =IFERROR(N(Sessions!AG3),0) -> 0 | O2: =IFERROR(N(Sessions!AI3),0) -> 0 | P2: =IFERROR(N(Sessions!AK3),0) -> 0 | Q2: =IFERROR(N(Sessions!AN3),0) -> 0 | R2: =IFERROR(N(Sessions!AP3),0) -> 0 | S2: =IFERROR(N(Sessions!AR3),0) -> 0 | T2: =IFERROR(N(Sessions!AU3),0) -> 0 | U2: =IFERROR(N(Sessions!AW3),0) -> 0 | V2: =IFERROR(N(Sessions!AY3),0) -> 0 | W2: =IFERROR(N(Sessions!BB3),0) -> 0 | X2: =IFERROR(N(Sessions!BD3),0) -> 0 | Y2: =IFERROR(N(Sessions!BF3),0) -> 0 | Z2: =IFERROR(N(Sessions!BI3),0) -> 0 | AA2: =IFERROR(N(Sessions!BK3),0) -> 0 | AB2: =IFERROR(N(Sessions!BM3),0) -> 0 | AC2: =IFERROR(N(Sessions!BP3),0) -> 0 | AD2: =IFERROR(N(Sessions!BR3),0) -> 0 | AE2: =IFERROR(N(Sessions!BT3),0) -> 0 | AF2: =IFERROR(N(Sessions!BW3),0) -> 0 | AG2: =IFERROR(N(Sessions!BY3),0) -> 0 | AH2: =IFERROR(N(Sessions!CA3),0) -> 0 | AI2: =IFERROR(N(Sessions!CD3),0) -> 0 | AJ2: =IFERROR(N(Sessions!CF3),0) -> 0 | AK2: =IFERROR(N(Sessions!CH3),0) -> 0 | AL2: =IFERROR(N(Sessions!F3),0) -> 0 | AM2: =IFERROR(N(Sessions!H3),0) -> 0 | AN2: =IFERROR(N(Sessions!J3),0) -> 0 | AO2: =IFERROR(N(Sessions!M3),0) -> 0 | AP2: =IFERROR(N(Sessions!O3),0) -> 0 | AQ2: =IFERROR(N(Sessions!Q3),0) -> 0 | AR2: =IFERROR(N(Sessions!T3),0) -> 0 | AS2: =IFERROR(N(Sessions!V3),0) -> 0 | AT2: =IFERROR(N(Sessions!X3),0) -> 0 | AU2: =IFERROR(N(Sessions!AA3),0) -> 0 | AV2: =IFERROR(N(Sessions!AC3),0) -> 0 | AW2: =IFERROR(N(Sessions!AE3),0) -> 0 | AX2: =IFERROR(N(Sessions!AH3),0) -> 0 | AY2: =IFERROR(N(Sessions!AJ3),0) -> 0 | AZ2: =IFERROR(N(Sessions!AL3),0) -> 0 | BA2: =IFERROR(N(Sessions!AO3),0) -> 0 | BB2: =IFERROR(N(Sessions!AQ3),0) -> 0 | BC2: =IFERROR(N(Sessions!AS3),0) -> 0 | BD2: =IFERROR(N(Sessions!AV3),0) -> 0 | BE2: =IFERROR(N(Sessions!AX3),0) -> 0 | BF2: =IFERROR(N(Sessions!AZ3),0) -> 0 | BG2: =IFERROR(N(Sessions!BC3),0) -> 0 | BH2: =IFERROR(N(Sessions!BE3),0) -> 0 | BI2: =IFERROR(N(Sessions!BG3),0) -> 0 | BJ2: =IFERROR(N(Sessions!BJ3),0) -> 0 | BK2: =IFERROR(N(Sessions!BL3),0) -> 0 | BL2: =IFERROR(N(Sessions!BN3),0) -> 0 | BM2: =IFERROR(N(Sessions!BQ3),0) -> 0 | BN2: =IFERROR(N(Sessions!BS3),0) -> 0 | BO2: =IFERROR(N(Sessions!BU3),0) -> 0 | BP2: =IFERROR(N(Sessions!BX3),0) -> 0 | BQ2: =IFERROR(N(Sessions!BZ3),0) -> 0 | BR2: =IFERROR(N(Sessions!CB3),0) -> 0 | BS2: =IFERROR(N(Sessions!CE3),0) -> 0 | BT2: =IFERROR(N(Sessions!CG3),0) -> 0 | BU2: =IFERROR(N(Sessions!CI3),0) -> 0 | BV2: =IF(B2=0,0,IFERROR(N(Sessions!D3),0)) -> 0 | BW2: =IF(C2=0,0,IFERROR(N(Sessions!D3),0)) -> 0 | BX2: =IF(D2=0,0,IFERROR(N(Sessions!D3),0)) -> 0 | BY2: =IF(E2=0,0,IFERROR(N(Sessions!K3),0)) -> 0 | BZ2: =IF(F2=0,0,IFERROR(N(Sessions!K3),0)) -> 0 | CA2: =IF(G2=0,0,IFERROR(N(Sessions!K3),0)) -> 0 | CB2: =IF(H2=0,0,IFERROR(N(Sessions!R3),0)) -> 0 | CC2: =IF(I2=0,0,IFERROR(N(Sessions!R3),0)) -> 0 | CD2: =IF(J2=0,0,IFERROR(N(Sessions!R3),0)) -> 0 | CE2: =IF(K2=0,0,IFERROR(N(Sessions!Y3),0)) -> 0 | CF2: =IF(L2=0,0,IFERROR(N(Sessions!Y3),0)) -> 0 | CG2: =IF(M2=0,0,IFERROR(N(Sessions!Y3),0)) -> 0 | CH2: =IF(N2=0,0,IFERROR(N(Sessions!AF3),0)) -> 0 | CI2: =IF(O2=0,0,IFERROR(N(Sessions!AF3),0)) -> 0 | CJ2: =IF(P2=0,0,IFERROR(N(Sessions!AF3),0)) -> 0 | CK2: =IF(Q2=0,0,IFERROR(N(Sessions!AM3),0)) -> 0 | CL2: =IF(R2=0,0,IFERROR(N(Sessions!AM3),0)) -> 0 | CM2: =IF(S2=0,0,IFERROR(N(Sessions!AM3),0)) -> 0 | CN2: =IF(T2=0,0,IFERROR(N(Sessions!AT3),0)) -> 0 | CO2: =IF(U2=0,0,IFERROR(N(Sessions!AT3),0)) -> 0 | CP2: =IF(V2=0,0,IFERROR(N(Sessions!AT3),0)) -> 0 | CQ2: =IF(W2=0,0,IFERROR(N(Sessions!BA3),0)) -> 0 | CR2: =IF(X2=0,0,IFERROR(N(Sessions!BA3),0)) -> 0 | CS2: =IF(Y2=0,0,IFERROR(N(Sessions!BA3),0)) -> 0 | CT2: =IF(Z2=0,0,IFERROR(N(Sessions!BH3),0)) -> 0 | CU2: =IF(AA2=0,0,IFERROR(N(Sessions!BH3),0)) -> 0 | CV2: =IF(AB2=0,0,IFERROR(N(Sessions!BH3),0)) -> 0 | CW2: =IF(AC2=0,0,IFERROR(N(Sessions!BO3),0)) -> 0 | CX2: =IF(AD2=0,0,IFERROR(N(Sessions!BO3),0)) -> 0 | CY2: =IF(AE2=0,0,IFERROR(N(Sessions!BO3),0)) -> 0 | CZ2: =IF(AF2=0,0,IFERROR(N(Sessions!BV3),0)) -> 0 | DA2: =IF(AG2=0,0,IFERROR(N(Sessions!BV3),0)) -> 0 | DB2: =IF(AH2=0,0,IFERROR(N(Sessions!BV3),0)) -> 0 | DC2: =IF(AI2=0,0,IFERROR(N(Sessions!CC3),0)) -> 0 | DD2: =IF(AJ2=0,0,IFERROR(N(Sessions!CC3),0)) -> 0 | DE2: =IF(AK2=0,0,IFERROR(N(Sessions!CC3),0)) -> 0 | DF2: =B2*100000+AL2 -> 3000000 | DG2: =C2*100000+AM2 -> 0 | DH2: =D2*100000+AN2 -> 0 | DI2: =E2*100000+AO2 -> 0 | DJ2: =F2*100000+AP2 -> 0 | DK2: =G2*100000+AQ2 -> 0 | DL2: =H2*100000+AR2 -> 0 | DM2: =I2*100000+AS2 -> 0 | ... EO2: =AK2*100000+BU2 -> 0
A3: =Sessions!B4 -> Lying Hamstring Curl | B3: =IFERROR(N(Sessions!E4),0) -> 35 | C3: =IFERROR(N(Sessions!G4),0) -> 0 | D3: =IFERROR(N(Sessions!I4),0) -> 0 | E3: =IFERROR(N(Sessions!L4),0) -> 0 | F3: =IFERROR(N(Sessions!N4),0) -> 0 | G3: =IFERROR(N(Sessions!P4),0) -> 0 | H3: =IFERROR(N(Sessions!S4),0) -> 0 | I3: =IFERROR(N(Sessions!U4),0) -> 0 | J3: =IFERROR(N(Sessions!W4),0) -> 0 | K3: =IFERROR(N(Sessions!Z4),0) -> 0 | L3: =IFERROR(N(Sessions!AB4),0) -> 0 | M3: =IFERROR(N(Sessions!AD4),0) -> 0 | N3: =IFERROR(N(Sessions!AG4),0) -> 0 | O3: =IFERROR(N(Sessions!AI4),0) -> 0 | P3: =IFERROR(N(Sessions!AK4),0) -> 0 | Q3: =IFERROR(N(Sessions!AN4),0) -> 0 | R3: =IFERROR(N(Sessions!AP4),0) -> 0 | S3: =IFERROR(N(Sessions!AR4),0) -> 0 | T3: =IFERROR(N(Sessions!AU4),0) -> 0 | U3: =IFERROR(N(Sessions!AW4),0) -> 0 | V3: =IFERROR(N(Sessions!AY4),0) -> 0 | W3: =IFERROR(N(Sessions!BB4),0) -> 0 | X3: =IFERROR(N(Sessions!BD4),0) -> 0 | Y3: =IFERROR(N(Sessions!BF4),0) -> 0 | Z3: =IFERROR(N(Sessions!BI4),0) -> 0 | AA3: =IFERROR(N(Sessions!BK4),0) -> 0 | AB3: =IFERROR(N(Sessions!BM4),0) -> 0 | AC3: =IFERROR(N(Sessions!BP4),0) -> 0 | AD3: =IFERROR(N(Sessions!BR4),0) -> 0 | AE3: =IFERROR(N(Sessions!BT4),0) -> 0 | AF3: =IFERROR(N(Sessions!BW4),0) -> 0 | AG3: =IFERROR(N(Sessions!BY4),0) -> 0 | AH3: =IFERROR(N(Sessions!CA4),0) -> 0 | AI3: =IFERROR(N(Sessions!CD4),0) -> 0 | AJ3: =IFERROR(N(Sessions!CF4),0) -> 0 | AK3: =IFERROR(N(Sessions!CH4),0) -> 0 | AL3: =IFERROR(N(Sessions!F4),0) -> 0 | AM3: =IFERROR(N(Sessions!H4),0) -> 0 | AN3: =IFERROR(N(Sessions!J4),0) -> 0 | AO3: =IFERROR(N(Sessions!M4),0) -> 0 | AP3: =IFERROR(N(Sessions!O4),0) -> 0 | AQ3: =IFERROR(N(Sessions!Q4),0) -> 0 | AR3: =IFERROR(N(Sessions!T4),0) -> 0 | AS3: =IFERROR(N(Sessions!V4),0) -> 0 | AT3: =IFERROR(N(Sessions!X4),0) -> 0 | AU3: =IFERROR(N(Sessions!AA4),0) -> 0 | AV3: =IFERROR(N(Sessions!AC4),0) -> 0 | AW3: =IFERROR(N(Sessions!AE4),0) -> 0 | AX3: =IFERROR(N(Sessions!AH4),0) -> 0 | AY3: =IFERROR(N(Sessions!AJ4),0) -> 0 | AZ3: =IFERROR(N(Sessions!AL4),0) -> 0 | BA3: =IFERROR(N(Sessions!AO4),0) -> 0 | BB3: =IFERROR(N(Sessions!AQ4),0) -> 0 | BC3: =IFERROR(N(Sessions!AS4),0) -> 0 | BD3: =IFERROR(N(Sessions!AV4),0) -> 0 | BE3: =IFERROR(N(Sessions!AX4),0) -> 0 | BF3: =IFERROR(N(Sessions!AZ4),0) -> 0 | BG3: =IFERROR(N(Sessions!BC4),0) -> 0 | BH3: =IFERROR(N(Sessions!BE4),0) -> 0 | BI3: =IFERROR(N(Sessions!BG4),0) -> 0 | BJ3: =IFERROR(N(Sessions!BJ4),0) -> 0 | BK3: =IFERROR(N(Sessions!BL4),0) -> 0 | BL3: =IFERROR(N(Sessions!BN4),0) -> 0 | BM3: =IFERROR(N(Sessions!BQ4),0) -> 0 | BN3: =IFERROR(N(Sessions!BS4),0) -> 0 | BO3: =IFERROR(N(Sessions!BU4),0) -> 0 | BP3: =IFERROR(N(Sessions!BX4),0) -> 0 | BQ3: =IFERROR(N(Sessions!BZ4),0) -> 0 | BR3: =IFERROR(N(Sessions!CB4),0) -> 0 | BS3: =IFERROR(N(Sessions!CE4),0) -> 0 | BT3: =IFERROR(N(Sessions!CG4),0) -> 0 | BU3: =IFERROR(N(Sessions!CI4),0) -> 0 | BV3: =IF(B3=0,0,IFERROR(N(Sessions!D4),0)) -> 0 | BW3: =IF(C3=0,0,IFERROR(N(Sessions!D4),0)) -> 0 | BX3: =IF(D3=0,0,IFERROR(N(Sessions!D4),0)) -> 0 | BY3: =IF(E3=0,0,IFERROR(N(Sessions!K4),0)) -> 0 | BZ3: =IF(F3=0,0,IFERROR(N(Sessions!K4),0)) -> 0 | CA3: =IF(G3=0,0,IFERROR(N(Sessions!K4),0)) -> 0 | CB3: =IF(H3=0,0,IFERROR(N(Sessions!R4),0)) -> 0 | CC3: =IF(I3=0,0,IFERROR(N(Sessions!R4),0)) -> 0 | CD3: =IF(J3=0,0,IFERROR(N(Sessions!R4),0)) -> 0 | CE3: =IF(K3=0,0,IFERROR(N(Sessions!Y4),0)) -> 0 | CF3: =IF(L3=0,0,IFERROR(N(Sessions!Y4),0)) -> 0 | CG3: =IF(M3=0,0,IFERROR(N(Sessions!Y4),0)) -> 0 | CH3: =IF(N3=0,0,IFERROR(N(Sessions!AF4),0)) -> 0 | CI3: =IF(O3=0,0,IFERROR(N(Sessions!AF4),0)) -> 0 | CJ3: =IF(P3=0,0,IFERROR(N(Sessions!AF4),0)) -> 0 | CK3: =IF(Q3=0,0,IFERROR(N(Sessions!AM4),0)) -> 0 | CL3: =IF(R3=0,0,IFERROR(N(Sessions!AM4),0)) -> 0 | CM3: =IF(S3=0,0,IFERROR(N(Sessions!AM4),0)) -> 0 | CN3: =IF(T3=0,0,IFERROR(N(Sessions!AT4),0)) -> 0 | CO3: =IF(U3=0,0,IFERROR(N(Sessions!AT4),0)) -> 0 | CP3: =IF(V3=0,0,IFERROR(N(Sessions!AT4),0)) -> 0 | CQ3: =IF(W3=0,0,IFERROR(N(Sessions!BA4),0)) -> 0 | CR3: =IF(X3=0,0,IFERROR(N(Sessions!BA4),0)) -> 0 | CS3: =IF(Y3=0,0,IFERROR(N(Sessions!BA4),0)) -> 0 | CT3: =IF(Z3=0,0,IFERROR(N(Sessions!BH4),0)) -> 0 | CU3: =IF(AA3=0,0,IFERROR(N(Sessions!BH4),0)) -> 0 | CV3: =IF(AB3=0,0,IFERROR(N(Sessions!BH4),0)) -> 0 | CW3: =IF(AC3=0,0,IFERROR(N(Sessions!BO4),0)) -> 0 | CX3: =IF(AD3=0,0,IFERROR(N(Sessions!BO4),0)) -> 0 | CY3: =IF(AE3=0,0,IFERROR(N(Sessions!BO4),0)) -> 0 | CZ3: =IF(AF3=0,0,IFERROR(N(Sessions!BV4),0)) -> 0 | DA3: =IF(AG3=0,0,IFERROR(N(Sessions!BV4),0)) -> 0 | DB3: =IF(AH3=0,0,IFERROR(N(Sessions!BV4),0)) -> 0 | DC3: =IF(AI3=0,0,IFERROR(N(Sessions!CC4),0)) -> 0 | DD3: =IF(AJ3=0,0,IFERROR(N(Sessions!CC4),0)) -> 0 | DE3: =IF(AK3=0,0,IFERROR(N(Sessions!CC4),0)) -> 0 | DF3: =B3*100000+AL3 -> 3500000 | DG3: =C3*100000+AM3 -> 0 | DH3: =D3*100000+AN3 -> 0 | DI3: =E3*100000+AO3 -> 0 | DJ3: =F3*100000+AP3 -> 0 | DK3: =G3*100000+AQ3 -> 0 | DL3: =H3*100000+AR3 -> 0 | DM3: =I3*100000+AS3 -> 0 | ... EO3: =AK3*100000+BU3 -> 0
A4: =Sessions!B5 -> Low Box Step Up | B4: =IFERROR(N(Sessions!E5),0) -> 24 | C4: =IFERROR(N(Sessions!G5),0) -> 0 | D4: =IFERROR(N(Sessions!I5),0) -> 0 | E4: =IFERROR(N(Sessions!L5),0) -> 0 | F4: =IFERROR(N(Sessions!N5),0) -> 0 | G4: =IFERROR(N(Sessions!P5),0) -> 0 | H4: =IFERROR(N(Sessions!S5),0) -> 0 | I4: =IFERROR(N(Sessions!U5),0) -> 0 | J4: =IFERROR(N(Sessions!W5),0) -> 0 | K4: =IFERROR(N(Sessions!Z5),0) -> 0 | L4: =IFERROR(N(Sessions!AB5),0) -> 0 | M4: =IFERROR(N(Sessions!AD5),0) -> 0 | N4: =IFERROR(N(Sessions!AG5),0) -> 0 | O4: =IFERROR(N(Sessions!AI5),0) -> 0 | P4: =IFERROR(N(Sessions!AK5),0) -> 0 | Q4: =IFERROR(N(Sessions!AN5),0) -> 0 | R4: =IFERROR(N(Sessions!AP5),0) -> 0 | S4: =IFERROR(N(Sessions!AR5),0) -> 0 | T4: =IFERROR(N(Sessions!AU5),0) -> 0 | U4: =IFERROR(N(Sessions!AW5),0) -> 0 | V4: =IFERROR(N(Sessions!AY5),0) -> 0 | W4: =IFERROR(N(Sessions!BB5),0) -> 0 | X4: =IFERROR(N(Sessions!BD5),0) -> 0 | Y4: =IFERROR(N(Sessions!BF5),0) -> 0 | Z4: =IFERROR(N(Sessions!BI5),0) -> 0 | AA4: =IFERROR(N(Sessions!BK5),0) -> 0 | AB4: =IFERROR(N(Sessions!BM5),0) -> 0 | AC4: =IFERROR(N(Sessions!BP5),0) -> 0 | AD4: =IFERROR(N(Sessions!BR5),0) -> 0 | AE4: =IFERROR(N(Sessions!BT5),0) -> 0 | AF4: =IFERROR(N(Sessions!BW5),0) -> 0 | AG4: =IFERROR(N(Sessions!BY5),0) -> 0 | AH4: =IFERROR(N(Sessions!CA5),0) -> 0 | AI4: =IFERROR(N(Sessions!CD5),0) -> 0 | AJ4: =IFERROR(N(Sessions!CF5),0) -> 0 | AK4: =IFERROR(N(Sessions!CH5),0) -> 0 | AL4: =IFERROR(N(Sessions!F5),0) -> 0 | AM4: =IFERROR(N(Sessions!H5),0) -> 0 | AN4: =IFERROR(N(Sessions!J5),0) -> 0 | AO4: =IFERROR(N(Sessions!M5),0) -> 0 | AP4: =IFERROR(N(Sessions!O5),0) -> 0 | AQ4: =IFERROR(N(Sessions!Q5),0) -> 0 | AR4: =IFERROR(N(Sessions!T5),0) -> 0 | AS4: =IFERROR(N(Sessions!V5),0) -> 0 | AT4: =IFERROR(N(Sessions!X5),0) -> 0 | AU4: =IFERROR(N(Sessions!AA5),0) -> 0 | AV4: =IFERROR(N(Sessions!AC5),0) -> 0 | AW4: =IFERROR(N(Sessions!AE5),0) -> 0 | AX4: =IFERROR(N(Sessions!AH5),0) -> 0 | AY4: =IFERROR(N(Sessions!AJ5),0) -> 0 | AZ4: =IFERROR(N(Sessions!AL5),0) -> 0 | BA4: =IFERROR(N(Sessions!AO5),0) -> 0 | BB4: =IFERROR(N(Sessions!AQ5),0) -> 0 | BC4: =IFERROR(N(Sessions!AS5),0) -> 0 | BD4: =IFERROR(N(Sessions!AV5),0) -> 0 | BE4: =IFERROR(N(Sessions!AX5),0) -> 0 | BF4: =IFERROR(N(Sessions!AZ5),0) -> 0 | BG4: =IFERROR(N(Sessions!BC5),0) -> 0 | BH4: =IFERROR(N(Sessions!BE5),0) -> 0 | BI4: =IFERROR(N(Sessions!BG5),0) -> 0 | BJ4: =IFERROR(N(Sessions!BJ5),0) -> 0 | BK4: =IFERROR(N(Sessions!BL5),0) -> 0 | BL4: =IFERROR(N(Sessions!BN5),0) -> 0 | BM4: =IFERROR(N(Sessions!BQ5),0) -> 0 | BN4: =IFERROR(N(Sessions!BS5),0) -> 0 | BO4: =IFERROR(N(Sessions!BU5),0) -> 0 | BP4: =IFERROR(N(Sessions!BX5),0) -> 0 | BQ4: =IFERROR(N(Sessions!BZ5),0) -> 0 | BR4: =IFERROR(N(Sessions!CB5),0) -> 0 | BS4: =IFERROR(N(Sessions!CE5),0) -> 0 | BT4: =IFERROR(N(Sessions!CG5),0) -> 0 | BU4: =IFERROR(N(Sessions!CI5),0) -> 0 | BV4: =IF(B4=0,0,IFERROR(N(Sessions!D5),0)) -> 0 | BW4: =IF(C4=0,0,IFERROR(N(Sessions!D5),0)) -> 0 | BX4: =IF(D4=0,0,IFERROR(N(Sessions!D5),0)) -> 0 | BY4: =IF(E4=0,0,IFERROR(N(Sessions!K5),0)) -> 0 | BZ4: =IF(F4=0,0,IFERROR(N(Sessions!K5),0)) -> 0 | CA4: =IF(G4=0,0,IFERROR(N(Sessions!K5),0)) -> 0 | CB4: =IF(H4=0,0,IFERROR(N(Sessions!R5),0)) -> 0 | CC4: =IF(I4=0,0,IFERROR(N(Sessions!R5),0)) -> 0 | CD4: =IF(J4=0,0,IFERROR(N(Sessions!R5),0)) -> 0 | CE4: =IF(K4=0,0,IFERROR(N(Sessions!Y5),0)) -> 0 | CF4: =IF(L4=0,0,IFERROR(N(Sessions!Y5),0)) -> 0 | CG4: =IF(M4=0,0,IFERROR(N(Sessions!Y5),0)) -> 0 | CH4: =IF(N4=0,0,IFERROR(N(Sessions!AF5),0)) -> 0 | CI4: =IF(O4=0,0,IFERROR(N(Sessions!AF5),0)) -> 0 | CJ4: =IF(P4=0,0,IFERROR(N(Sessions!AF5),0)) -> 0 | CK4: =IF(Q4=0,0,IFERROR(N(Sessions!AM5),0)) -> 0 | CL4: =IF(R4=0,0,IFERROR(N(Sessions!AM5),0)) -> 0 | CM4: =IF(S4=0,0,IFERROR(N(Sessions!AM5),0)) -> 0 | CN4: =IF(T4=0,0,IFERROR(N(Sessions!AT5),0)) -> 0 | CO4: =IF(U4=0,0,IFERROR(N(Sessions!AT5),0)) -> 0 | CP4: =IF(V4=0,0,IFERROR(N(Sessions!AT5),0)) -> 0 | CQ4: =IF(W4=0,0,IFERROR(N(Sessions!BA5),0)) -> 0 | CR4: =IF(X4=0,0,IFERROR(N(Sessions!BA5),0)) -> 0 | CS4: =IF(Y4=0,0,IFERROR(N(Sessions!BA5),0)) -> 0 | CT4: =IF(Z4=0,0,IFERROR(N(Sessions!BH5),0)) -> 0 | CU4: =IF(AA4=0,0,IFERROR(N(Sessions!BH5),0)) -> 0 | CV4: =IF(AB4=0,0,IFERROR(N(Sessions!BH5),0)) -> 0 | CW4: =IF(AC4=0,0,IFERROR(N(Sessions!BO5),0)) -> 0 | CX4: =IF(AD4=0,0,IFERROR(N(Sessions!BO5),0)) -> 0 | CY4: =IF(AE4=0,0,IFERROR(N(Sessions!BO5),0)) -> 0 | CZ4: =IF(AF4=0,0,IFERROR(N(Sessions!BV5),0)) -> 0 | DA4: =IF(AG4=0,0,IFERROR(N(Sessions!BV5),0)) -> 0 | DB4: =IF(AH4=0,0,IFERROR(N(Sessions!BV5),0)) -> 0 | DC4: =IF(AI4=0,0,IFERROR(N(Sessions!CC5),0)) -> 0 | DD4: =IF(AJ4=0,0,IFERROR(N(Sessions!CC5),0)) -> 0 | DE4: =IF(AK4=0,0,IFERROR(N(Sessions!CC5),0)) -> 0 | DF4: =B4*100000+AL4 -> 2400000 | DG4: =C4*100000+AM4 -> 0 | DH4: =D4*100000+AN4 -> 0 | DI4: =E4*100000+AO4 -> 0 | DJ4: =F4*100000+AP4 -> 0 | DK4: =G4*100000+AQ4 -> 0 | DL4: =H4*100000+AR4 -> 0 | DM4: =I4*100000+AS4 -> 0 | ... EO4: =AK4*100000+BU4 -> 0
A5: =Sessions!B6 -> Goblet Squat | B5: =IFERROR(N(Sessions!E6),0) -> 12 | C5: =IFERROR(N(Sessions!G6),0) -> 0 | D5: =IFERROR(N(Sessions!I6),0) -> 0 | E5: =IFERROR(N(Sessions!L6),0) -> 0 | F5: =IFERROR(N(Sessions!N6),0) -> 0 | G5: =IFERROR(N(Sessions!P6),0) -> 0 | H5: =IFERROR(N(Sessions!S6),0) -> 0 | I5: =IFERROR(N(Sessions!U6),0) -> 0 | J5: =IFERROR(N(Sessions!W6),0) -> 0 | K5: =IFERROR(N(Sessions!Z6),0) -> 0 | L5: =IFERROR(N(Sessions!AB6),0) -> 0 | M5: =IFERROR(N(Sessions!AD6),0) -> 0 | N5: =IFERROR(N(Sessions!AG6),0) -> 0 | O5: =IFERROR(N(Sessions!AI6),0) -> 0 | P5: =IFERROR(N(Sessions!AK6),0) -> 0 | Q5: =IFERROR(N(Sessions!AN6),0) -> 0 | R5: =IFERROR(N(Sessions!AP6),0) -> 0 | S5: =IFERROR(N(Sessions!AR6),0) -> 0 | T5: =IFERROR(N(Sessions!AU6),0) -> 0 | U5: =IFERROR(N(Sessions!AW6),0) -> 0 | V5: =IFERROR(N(Sessions!AY6),0) -> 0 | W5: =IFERROR(N(Sessions!BB6),0) -> 0 | X5: =IFERROR(N(Sessions!BD6),0) -> 0 | Y5: =IFERROR(N(Sessions!BF6),0) -> 0 | Z5: =IFERROR(N(Sessions!BI6),0) -> 0 | AA5: =IFERROR(N(Sessions!BK6),0) -> 0 | AB5: =IFERROR(N(Sessions!BM6),0) -> 0 | AC5: =IFERROR(N(Sessions!BP6),0) -> 0 | AD5: =IFERROR(N(Sessions!BR6),0) -> 0 | AE5: =IFERROR(N(Sessions!BT6),0) -> 0 | AF5: =IFERROR(N(Sessions!BW6),0) -> 0 | AG5: =IFERROR(N(Sessions!BY6),0) -> 0 | AH5: =IFERROR(N(Sessions!CA6),0) -> 0 | AI5: =IFERROR(N(Sessions!CD6),0) -> 0 | AJ5: =IFERROR(N(Sessions!CF6),0) -> 0 | AK5: =IFERROR(N(Sessions!CH6),0) -> 0 | AL5: =IFERROR(N(Sessions!F6),0) -> 0 | AM5: =IFERROR(N(Sessions!H6),0) -> 0 | AN5: =IFERROR(N(Sessions!J6),0) -> 0 | AO5: =IFERROR(N(Sessions!M6),0) -> 0 | AP5: =IFERROR(N(Sessions!O6),0) -> 0 | AQ5: =IFERROR(N(Sessions!Q6),0) -> 0 | AR5: =IFERROR(N(Sessions!T6),0) -> 0 | AS5: =IFERROR(N(Sessions!V6),0) -> 0 | AT5: =IFERROR(N(Sessions!X6),0) -> 0 | AU5: =IFERROR(N(Sessions!AA6),0) -> 0 | AV5: =IFERROR(N(Sessions!AC6),0) -> 0 | AW5: =IFERROR(N(Sessions!AE6),0) -> 0 | AX5: =IFERROR(N(Sessions!AH6),0) -> 0 | AY5: =IFERROR(N(Sessions!AJ6),0) -> 0 | AZ5: =IFERROR(N(Sessions!AL6),0) -> 0 | BA5: =IFERROR(N(Sessions!AO6),0) -> 0 | BB5: =IFERROR(N(Sessions!AQ6),0) -> 0 | BC5: =IFERROR(N(Sessions!AS6),0) -> 0 | BD5: =IFERROR(N(Sessions!AV6),0) -> 0 | BE5: =IFERROR(N(Sessions!AX6),0) -> 0 | BF5: =IFERROR(N(Sessions!AZ6),0) -> 0 | BG5: =IFERROR(N(Sessions!BC6),0) -> 0 | BH5: =IFERROR(N(Sessions!BE6),0) -> 0 | BI5: =IFERROR(N(Sessions!BG6),0) -> 0 | BJ5: =IFERROR(N(Sessions!BJ6),0) -> 0 | BK5: =IFERROR(N(Sessions!BL6),0) -> 0 | BL5: =IFERROR(N(Sessions!BN6),0) -> 0 | BM5: =IFERROR(N(Sessions!BQ6),0) -> 0 | BN5: =IFERROR(N(Sessions!BS6),0) -> 0 | BO5: =IFERROR(N(Sessions!BU6),0) -> 0 | BP5: =IFERROR(N(Sessions!BX6),0) -> 0 | BQ5: =IFERROR(N(Sessions!BZ6),0) -> 0 | BR5: =IFERROR(N(Sessions!CB6),0) -> 0 | BS5: =IFERROR(N(Sessions!CE6),0) -> 0 | BT5: =IFERROR(N(Sessions!CG6),0) -> 0 | BU5: =IFERROR(N(Sessions!CI6),0) -> 0 | BV5: =IF(B5=0,0,IFERROR(N(Sessions!D6),0)) -> 0 | BW5: =IF(C5=0,0,IFERROR(N(Sessions!D6),0)) -> 0 | BX5: =IF(D5=0,0,IFERROR(N(Sessions!D6),0)) -> 0 | BY5: =IF(E5=0,0,IFERROR(N(Sessions!K6),0)) -> 0 | BZ5: =IF(F5=0,0,IFERROR(N(Sessions!K6),0)) -> 0 | CA5: =IF(G5=0,0,IFERROR(N(Sessions!K6),0)) -> 0 | CB5: =IF(H5=0,0,IFERROR(N(Sessions!R6),0)) -> 0 | CC5: =IF(I5=0,0,IFERROR(N(Sessions!R6),0)) -> 0 | CD5: =IF(J5=0,0,IFERROR(N(Sessions!R6),0)) -> 0 | CE5: =IF(K5=0,0,IFERROR(N(Sessions!Y6),0)) -> 0 | CF5: =IF(L5=0,0,IFERROR(N(Sessions!Y6),0)) -> 0 | CG5: =IF(M5=0,0,IFERROR(N(Sessions!Y6),0)) -> 0 | CH5: =IF(N5=0,0,IFERROR(N(Sessions!AF6),0)) -> 0 | CI5: =IF(O5=0,0,IFERROR(N(Sessions!AF6),0)) -> 0 | CJ5: =IF(P5=0,0,IFERROR(N(Sessions!AF6),0)) -> 0 | CK5: =IF(Q5=0,0,IFERROR(N(Sessions!AM6),0)) -> 0 | CL5: =IF(R5=0,0,IFERROR(N(Sessions!AM6),0)) -> 0 | CM5: =IF(S5=0,0,IFERROR(N(Sessions!AM6),0)) -> 0 | CN5: =IF(T5=0,0,IFERROR(N(Sessions!AT6),0)) -> 0 | CO5: =IF(U5=0,0,IFERROR(N(Sessions!AT6),0)) -> 0 | CP5: =IF(V5=0,0,IFERROR(N(Sessions!AT6),0)) -> 0 | CQ5: =IF(W5=0,0,IFERROR(N(Sessions!BA6),0)) -> 0 | CR5: =IF(X5=0,0,IFERROR(N(Sessions!BA6),0)) -> 0 | CS5: =IF(Y5=0,0,IFERROR(N(Sessions!BA6),0)) -> 0 | CT5: =IF(Z5=0,0,IFERROR(N(Sessions!BH6),0)) -> 0 | CU5: =IF(AA5=0,0,IFERROR(N(Sessions!BH6),0)) -> 0 | CV5: =IF(AB5=0,0,IFERROR(N(Sessions!BH6),0)) -> 0 | CW5: =IF(AC5=0,0,IFERROR(N(Sessions!BO6),0)) -> 0 | CX5: =IF(AD5=0,0,IFERROR(N(Sessions!BO6),0)) -> 0 | CY5: =IF(AE5=0,0,IFERROR(N(Sessions!BO6),0)) -> 0 | CZ5: =IF(AF5=0,0,IFERROR(N(Sessions!BV6),0)) -> 0 | DA5: =IF(AG5=0,0,IFERROR(N(Sessions!BV6),0)) -> 0 | DB5: =IF(AH5=0,0,IFERROR(N(Sessions!BV6),0)) -> 0 | DC5: =IF(AI5=0,0,IFERROR(N(Sessions!CC6),0)) -> 0 | DD5: =IF(AJ5=0,0,IFERROR(N(Sessions!CC6),0)) -> 0 | DE5: =IF(AK5=0,0,IFERROR(N(Sessions!CC6),0)) -> 0 | DF5: =B5*100000+AL5 -> 1200000 | DG5: =C5*100000+AM5 -> 0 | DH5: =D5*100000+AN5 -> 0 | DI5: =E5*100000+AO5 -> 0 | DJ5: =F5*100000+AP5 -> 0 | DK5: =G5*100000+AQ5 -> 0 | DL5: =H5*100000+AR5 -> 0 | DM5: =I5*100000+AS5 -> 0 | ... EO5: =AK5*100000+BU5 -> 0
A6: =Sessions!B7 -> Pallof Press | B6: =IFERROR(N(Sessions!E7),0) -> 0 | C6: =IFERROR(N(Sessions!G7),0) -> 0 | D6: =IFERROR(N(Sessions!I7),0) -> 0 | E6: =IFERROR(N(Sessions!L7),0) -> 0 | F6: =IFERROR(N(Sessions!N7),0) -> 0 | G6: =IFERROR(N(Sessions!P7),0) -> 0 | H6: =IFERROR(N(Sessions!S7),0) -> 0 | I6: =IFERROR(N(Sessions!U7),0) -> 0 | J6: =IFERROR(N(Sessions!W7),0) -> 0 | K6: =IFERROR(N(Sessions!Z7),0) -> 0 | L6: =IFERROR(N(Sessions!AB7),0) -> 0 | M6: =IFERROR(N(Sessions!AD7),0) -> 0 | N6: =IFERROR(N(Sessions!AG7),0) -> 0 | O6: =IFERROR(N(Sessions!AI7),0) -> 0 | P6: =IFERROR(N(Sessions!AK7),0) -> 0 | Q6: =IFERROR(N(Sessions!AN7),0) -> 0 | R6: =IFERROR(N(Sessions!AP7),0) -> 0 | S6: =IFERROR(N(Sessions!AR7),0) -> 0 | T6: =IFERROR(N(Sessions!AU7),0) -> 0 | U6: =IFERROR(N(Sessions!AW7),0) -> 0 | V6: =IFERROR(N(Sessions!AY7),0) -> 0 | W6: =IFERROR(N(Sessions!BB7),0) -> 0 | X6: =IFERROR(N(Sessions!BD7),0) -> 0 | Y6: =IFERROR(N(Sessions!BF7),0) -> 0 | Z6: =IFERROR(N(Sessions!BI7),0) -> 0 | AA6: =IFERROR(N(Sessions!BK7),0) -> 0 | AB6: =IFERROR(N(Sessions!BM7),0) -> 0 | AC6: =IFERROR(N(Sessions!BP7),0) -> 0 | AD6: =IFERROR(N(Sessions!BR7),0) -> 0 | AE6: =IFERROR(N(Sessions!BT7),0) -> 0 | AF6: =IFERROR(N(Sessions!BW7),0) -> 0 | AG6: =IFERROR(N(Sessions!BY7),0) -> 0 | AH6: =IFERROR(N(Sessions!CA7),0) -> 0 | AI6: =IFERROR(N(Sessions!CD7),0) -> 0 | AJ6: =IFERROR(N(Sessions!CF7),0) -> 0 | AK6: =IFERROR(N(Sessions!CH7),0) -> 0 | AL6: =IFERROR(N(Sessions!F7),0) -> 0 | AM6: =IFERROR(N(Sessions!H7),0) -> 0 | AN6: =IFERROR(N(Sessions!J7),0) -> 0 | AO6: =IFERROR(N(Sessions!M7),0) -> 0 | AP6: =IFERROR(N(Sessions!O7),0) -> 0 | AQ6: =IFERROR(N(Sessions!Q7),0) -> 0 | AR6: =IFERROR(N(Sessions!T7),0) -> 0 | AS6: =IFERROR(N(Sessions!V7),0) -> 0 | AT6: =IFERROR(N(Sessions!X7),0) -> 0 | AU6: =IFERROR(N(Sessions!AA7),0) -> 0 | AV6: =IFERROR(N(Sessions!AC7),0) -> 0 | AW6: =IFERROR(N(Sessions!AE7),0) -> 0 | AX6: =IFERROR(N(Sessions!AH7),0) -> 0 | AY6: =IFERROR(N(Sessions!AJ7),0) -> 0 | AZ6: =IFERROR(N(Sessions!AL7),0) -> 0 | BA6: =IFERROR(N(Sessions!AO7),0) -> 0 | BB6: =IFERROR(N(Sessions!AQ7),0) -> 0 | BC6: =IFERROR(N(Sessions!AS7),0) -> 0 | BD6: =IFERROR(N(Sessions!AV7),0) -> 0 | BE6: =IFERROR(N(Sessions!AX7),0) -> 0 | BF6: =IFERROR(N(Sessions!AZ7),0) -> 0 | BG6: =IFERROR(N(Sessions!BC7),0) -> 0 | BH6: =IFERROR(N(Sessions!BE7),0) -> 0 | BI6: =IFERROR(N(Sessions!BG7),0) -> 0 | BJ6: =IFERROR(N(Sessions!BJ7),0) -> 0 | BK6: =IFERROR(N(Sessions!BL7),0) -> 0 | BL6: =IFERROR(N(Sessions!BN7),0) -> 0 | BM6: =IFERROR(N(Sessions!BQ7),0) -> 0 | BN6: =IFERROR(N(Sessions!BS7),0) -> 0 | BO6: =IFERROR(N(Sessions!BU7),0) -> 0 | BP6: =IFERROR(N(Sessions!BX7),0) -> 0 | BQ6: =IFERROR(N(Sessions!BZ7),0) -> 0 | BR6: =IFERROR(N(Sessions!CB7),0) -> 0 | BS6: =IFERROR(N(Sessions!CE7),0) -> 0 | BT6: =IFERROR(N(Sessions!CG7),0) -> 0 | BU6: =IFERROR(N(Sessions!CI7),0) -> 0 | BV6: =IF(B6=0,0,IFERROR(N(Sessions!D7),0)) -> 0 | BW6: =IF(C6=0,0,IFERROR(N(Sessions!D7),0)) -> 0 | BX6: =IF(D6=0,0,IFERROR(N(Sessions!D7),0)) -> 0 | BY6: =IF(E6=0,0,IFERROR(N(Sessions!K7),0)) -> 0 | BZ6: =IF(F6=0,0,IFERROR(N(Sessions!K7),0)) -> 0 | CA6: =IF(G6=0,0,IFERROR(N(Sessions!K7),0)) -> 0 | CB6: =IF(H6=0,0,IFERROR(N(Sessions!R7),0)) -> 0 | CC6: =IF(I6=0,0,IFERROR(N(Sessions!R7),0)) -> 0 | CD6: =IF(J6=0,0,IFERROR(N(Sessions!R7),0)) -> 0 | CE6: =IF(K6=0,0,IFERROR(N(Sessions!Y7),0)) -> 0 | CF6: =IF(L6=0,0,IFERROR(N(Sessions!Y7),0)) -> 0 | CG6: =IF(M6=0,0,IFERROR(N(Sessions!Y7),0)) -> 0 | CH6: =IF(N6=0,0,IFERROR(N(Sessions!AF7),0)) -> 0 | CI6: =IF(O6=0,0,IFERROR(N(Sessions!AF7),0)) -> 0 | CJ6: =IF(P6=0,0,IFERROR(N(Sessions!AF7),0)) -> 0 | CK6: =IF(Q6=0,0,IFERROR(N(Sessions!AM7),0)) -> 0 | CL6: =IF(R6=0,0,IFERROR(N(Sessions!AM7),0)) -> 0 | CM6: =IF(S6=0,0,IFERROR(N(Sessions!AM7),0)) -> 0 | CN6: =IF(T6=0,0,IFERROR(N(Sessions!AT7),0)) -> 0 | CO6: =IF(U6=0,0,IFERROR(N(Sessions!AT7),0)) -> 0 | CP6: =IF(V6=0,0,IFERROR(N(Sessions!AT7),0)) -> 0 | CQ6: =IF(W6=0,0,IFERROR(N(Sessions!BA7),0)) -> 0 | CR6: =IF(X6=0,0,IFERROR(N(Sessions!BA7),0)) -> 0 | CS6: =IF(Y6=0,0,IFERROR(N(Sessions!BA7),0)) -> 0 | CT6: =IF(Z6=0,0,IFERROR(N(Sessions!BH7),0)) -> 0 | CU6: =IF(AA6=0,0,IFERROR(N(Sessions!BH7),0)) -> 0 | CV6: =IF(AB6=0,0,IFERROR(N(Sessions!BH7),0)) -> 0 | CW6: =IF(AC6=0,0,IFERROR(N(Sessions!BO7),0)) -> 0 | CX6: =IF(AD6=0,0,IFERROR(N(Sessions!BO7),0)) -> 0 | CY6: =IF(AE6=0,0,IFERROR(N(Sessions!BO7),0)) -> 0 | CZ6: =IF(AF6=0,0,IFERROR(N(Sessions!BV7),0)) -> 0 | DA6: =IF(AG6=0,0,IFERROR(N(Sessions!BV7),0)) -> 0 | DB6: =IF(AH6=0,0,IFERROR(N(Sessions!BV7),0)) -> 0 | DC6: =IF(AI6=0,0,IFERROR(N(Sessions!CC7),0)) -> 0 | DD6: =IF(AJ6=0,0,IFERROR(N(Sessions!CC7),0)) -> 0 | DE6: =IF(AK6=0,0,IFERROR(N(Sessions!CC7),0)) -> 0 | DF6: =B6*100000+AL6 -> 0 | DG6: =C6*100000+AM6 -> 0 | DH6: =D6*100000+AN6 -> 0 | DI6: =E6*100000+AO6 -> 0 | DJ6: =F6*100000+AP6 -> 0 | DK6: =G6*100000+AQ6 -> 0 | DL6: =H6*100000+AR6 -> 0 | DM6: =I6*100000+AS6 -> 0 | ... EO6: =AK6*100000+BU6 -> 0
A7: =Sessions!B9 -> Barbell Romaniam Deadlift | B7: =IFERROR(N(Sessions!E9),0) -> 30 | C7: =IFERROR(N(Sessions!G9),0) -> 0 | D7: =IFERROR(N(Sessions!I9),0) -> 0 | E7: =IFERROR(N(Sessions!L9),0) -> 0 | F7: =IFERROR(N(Sessions!N9),0) -> 0 | G7: =IFERROR(N(Sessions!P9),0) -> 0 | H7: =IFERROR(N(Sessions!S9),0) -> 0 | I7: =IFERROR(N(Sessions!U9),0) -> 0 | J7: =IFERROR(N(Sessions!W9),0) -> 0 | K7: =IFERROR(N(Sessions!Z9),0) -> 0 | L7: =IFERROR(N(Sessions!AB9),0) -> 0 | M7: =IFERROR(N(Sessions!AD9),0) -> 0 | N7: =IFERROR(N(Sessions!AG9),0) -> 0 | O7: =IFERROR(N(Sessions!AI9),0) -> 0 | P7: =IFERROR(N(Sessions!AK9),0) -> 0 | Q7: =IFERROR(N(Sessions!AN9),0) -> 0 | R7: =IFERROR(N(Sessions!AP9),0) -> 0 | S7: =IFERROR(N(Sessions!AR9),0) -> 0 | T7: =IFERROR(N(Sessions!AU9),0) -> 0 | U7: =IFERROR(N(Sessions!AW9),0) -> 0 | V7: =IFERROR(N(Sessions!AY9),0) -> 0 | W7: =IFERROR(N(Sessions!BB9),0) -> 0 | X7: =IFERROR(N(Sessions!BD9),0) -> 0 | Y7: =IFERROR(N(Sessions!BF9),0) -> 0 | Z7: =IFERROR(N(Sessions!BI9),0) -> 0 | AA7: =IFERROR(N(Sessions!BK9),0) -> 0 | AB7: =IFERROR(N(Sessions!BM9),0) -> 0 | AC7: =IFERROR(N(Sessions!BP9),0) -> 0 | AD7: =IFERROR(N(Sessions!BR9),0) -> 0 | AE7: =IFERROR(N(Sessions!BT9),0) -> 0 | AF7: =IFERROR(N(Sessions!BW9),0) -> 0 | AG7: =IFERROR(N(Sessions!BY9),0) -> 0 | AH7: =IFERROR(N(Sessions!CA9),0) -> 0 | AI7: =IFERROR(N(Sessions!CD9),0) -> 0 | AJ7: =IFERROR(N(Sessions!CF9),0) -> 0 | AK7: =IFERROR(N(Sessions!CH9),0) -> 0 | AL7: =IFERROR(N(Sessions!F9),0) -> 0 | AM7: =IFERROR(N(Sessions!H9),0) -> 0 | AN7: =IFERROR(N(Sessions!J9),0) -> 0 | AO7: =IFERROR(N(Sessions!M9),0) -> 0 | AP7: =IFERROR(N(Sessions!O9),0) -> 0 | AQ7: =IFERROR(N(Sessions!Q9),0) -> 0 | AR7: =IFERROR(N(Sessions!T9),0) -> 0 | AS7: =IFERROR(N(Sessions!V9),0) -> 0 | AT7: =IFERROR(N(Sessions!X9),0) -> 0 | AU7: =IFERROR(N(Sessions!AA9),0) -> 0 | AV7: =IFERROR(N(Sessions!AC9),0) -> 0 | AW7: =IFERROR(N(Sessions!AE9),0) -> 0 | AX7: =IFERROR(N(Sessions!AH9),0) -> 0 | AY7: =IFERROR(N(Sessions!AJ9),0) -> 0 | AZ7: =IFERROR(N(Sessions!AL9),0) -> 0 | BA7: =IFERROR(N(Sessions!AO9),0) -> 0 | BB7: =IFERROR(N(Sessions!AQ9),0) -> 0 | BC7: =IFERROR(N(Sessions!AS9),0) -> 0 | BD7: =IFERROR(N(Sessions!AV9),0) -> 0 | BE7: =IFERROR(N(Sessions!AX9),0) -> 0 | BF7: =IFERROR(N(Sessions!AZ9),0) -> 0 | BG7: =IFERROR(N(Sessions!BC9),0) -> 0 | BH7: =IFERROR(N(Sessions!BE9),0) -> 0 | BI7: =IFERROR(N(Sessions!BG9),0) -> 0 | BJ7: =IFERROR(N(Sessions!BJ9),0) -> 0 | BK7: =IFERROR(N(Sessions!BL9),0) -> 0 | BL7: =IFERROR(N(Sessions!BN9),0) -> 0 | BM7: =IFERROR(N(Sessions!BQ9),0) -> 0 | BN7: =IFERROR(N(Sessions!BS9),0) -> 0 | BO7: =IFERROR(N(Sessions!BU9),0) -> 0 | BP7: =IFERROR(N(Sessions!BX9),0) -> 0 | BQ7: =IFERROR(N(Sessions!BZ9),0) -> 0 | BR7: =IFERROR(N(Sessions!CB9),0) -> 0 | BS7: =IFERROR(N(Sessions!CE9),0) -> 0 | BT7: =IFERROR(N(Sessions!CG9),0) -> 0 | BU7: =IFERROR(N(Sessions!CI9),0) -> 0 | BV7: =IF(B7=0,0,IFERROR(N(Sessions!D9),0)) -> 0 | BW7: =IF(C7=0,0,IFERROR(N(Sessions!D9),0)) -> 0 | BX7: =IF(D7=0,0,IFERROR(N(Sessions!D9),0)) -> 0 | BY7: =IF(E7=0,0,IFERROR(N(Sessions!K9),0)) -> 0 | BZ7: =IF(F7=0,0,IFERROR(N(Sessions!K9),0)) -> 0 | CA7: =IF(G7=0,0,IFERROR(N(Sessions!K9),0)) -> 0 | CB7: =IF(H7=0,0,IFERROR(N(Sessions!R9),0)) -> 0 | CC7: =IF(I7=0,0,IFERROR(N(Sessions!R9),0)) -> 0 | CD7: =IF(J7=0,0,IFERROR(N(Sessions!R9),0)) -> 0 | CE7: =IF(K7=0,0,IFERROR(N(Sessions!Y9),0)) -> 0 | CF7: =IF(L7=0,0,IFERROR(N(Sessions!Y9),0)) -> 0 | CG7: =IF(M7=0,0,IFERROR(N(Sessions!Y9),0)) -> 0 | CH7: =IF(N7=0,0,IFERROR(N(Sessions!AF9),0)) -> 0 | CI7: =IF(O7=0,0,IFERROR(N(Sessions!AF9),0)) -> 0 | CJ7: =IF(P7=0,0,IFERROR(N(Sessions!AF9),0)) -> 0 | CK7: =IF(Q7=0,0,IFERROR(N(Sessions!AM9),0)) -> 0 | CL7: =IF(R7=0,0,IFERROR(N(Sessions!AM9),0)) -> 0 | CM7: =IF(S7=0,0,IFERROR(N(Sessions!AM9),0)) -> 0 | CN7: =IF(T7=0,0,IFERROR(N(Sessions!AT9),0)) -> 0 | CO7: =IF(U7=0,0,IFERROR(N(Sessions!AT9),0)) -> 0 | CP7: =IF(V7=0,0,IFERROR(N(Sessions!AT9),0)) -> 0 | CQ7: =IF(W7=0,0,IFERROR(N(Sessions!BA9),0)) -> 0 | CR7: =IF(X7=0,0,IFERROR(N(Sessions!BA9),0)) -> 0 | CS7: =IF(Y7=0,0,IFERROR(N(Sessions!BA9),0)) -> 0 | CT7: =IF(Z7=0,0,IFERROR(N(Sessions!BH9),0)) -> 0 | CU7: =IF(AA7=0,0,IFERROR(N(Sessions!BH9),0)) -> 0 | CV7: =IF(AB7=0,0,IFERROR(N(Sessions!BH9),0)) -> 0 | CW7: =IF(AC7=0,0,IFERROR(N(Sessions!BO9),0)) -> 0 | CX7: =IF(AD7=0,0,IFERROR(N(Sessions!BO9),0)) -> 0 | CY7: =IF(AE7=0,0,IFERROR(N(Sessions!BO9),0)) -> 0 | CZ7: =IF(AF7=0,0,IFERROR(N(Sessions!BV9),0)) -> 0 | DA7: =IF(AG7=0,0,IFERROR(N(Sessions!BV9),0)) -> 0 | DB7: =IF(AH7=0,0,IFERROR(N(Sessions!BV9),0)) -> 0 | DC7: =IF(AI7=0,0,IFERROR(N(Sessions!CC9),0)) -> 0 | DD7: =IF(AJ7=0,0,IFERROR(N(Sessions!CC9),0)) -> 0 | DE7: =IF(AK7=0,0,IFERROR(N(Sessions!CC9),0)) -> 0 | DF7: =B7*100000+AL7 -> 3000000 | DG7: =C7*100000+AM7 -> 0 | DH7: =D7*100000+AN7 -> 0 | DI7: =E7*100000+AO7 -> 0 | DJ7: =F7*100000+AP7 -> 0 | DK7: =G7*100000+AQ7 -> 0 | DL7: =H7*100000+AR7 -> 0 | DM7: =I7*100000+AS7 -> 0 | ... EO7: =AK7*100000+BU7 -> 0
A8: =Sessions!B10 -> Dumbbell Bulgarian Split Squat | B8: =IFERROR(N(Sessions!E10),0) -> 5 | C8: =IFERROR(N(Sessions!G10),0) -> 0 | D8: =IFERROR(N(Sessions!I10),0) -> 0 | E8: =IFERROR(N(Sessions!L10),0) -> 0 | F8: =IFERROR(N(Sessions!N10),0) -> 0 | G8: =IFERROR(N(Sessions!P10),0) -> 0 | H8: =IFERROR(N(Sessions!S10),0) -> 0 | I8: =IFERROR(N(Sessions!U10),0) -> 0 | J8: =IFERROR(N(Sessions!W10),0) -> 0 | K8: =IFERROR(N(Sessions!Z10),0) -> 0 | L8: =IFERROR(N(Sessions!AB10),0) -> 0 | M8: =IFERROR(N(Sessions!AD10),0) -> 0 | N8: =IFERROR(N(Sessions!AG10),0) -> 0 | O8: =IFERROR(N(Sessions!AI10),0) -> 0 | P8: =IFERROR(N(Sessions!AK10),0) -> 0 | Q8: =IFERROR(N(Sessions!AN10),0) -> 0 | R8: =IFERROR(N(Sessions!AP10),0) -> 0 | S8: =IFERROR(N(Sessions!AR10),0) -> 0 | T8: =IFERROR(N(Sessions!AU10),0) -> 0 | U8: =IFERROR(N(Sessions!AW10),0) -> 0 | V8: =IFERROR(N(Sessions!AY10),0) -> 0 | W8: =IFERROR(N(Sessions!BB10),0) -> 0 | X8: =IFERROR(N(Sessions!BD10),0) -> 0 | Y8: =IFERROR(N(Sessions!BF10),0) -> 0 | Z8: =IFERROR(N(Sessions!BI10),0) -> 0 | AA8: =IFERROR(N(Sessions!BK10),0) -> 0 | AB8: =IFERROR(N(Sessions!BM10),0) -> 0 | AC8: =IFERROR(N(Sessions!BP10),0) -> 0 | AD8: =IFERROR(N(Sessions!BR10),0) -> 0 | AE8: =IFERROR(N(Sessions!BT10),0) -> 0 | AF8: =IFERROR(N(Sessions!BW10),0) -> 0 | AG8: =IFERROR(N(Sessions!BY10),0) -> 0 | AH8: =IFERROR(N(Sessions!CA10),0) -> 0 | AI8: =IFERROR(N(Sessions!CD10),0) -> 0 | AJ8: =IFERROR(N(Sessions!CF10),0) -> 0 | AK8: =IFERROR(N(Sessions!CH10),0) -> 0 | AL8: =IFERROR(N(Sessions!F10),0) -> 0 | AM8: =IFERROR(N(Sessions!H10),0) -> 0 | AN8: =IFERROR(N(Sessions!J10),0) -> 0 | AO8: =IFERROR(N(Sessions!M10),0) -> 0 | AP8: =IFERROR(N(Sessions!O10),0) -> 0 | AQ8: =IFERROR(N(Sessions!Q10),0) -> 0 | AR8: =IFERROR(N(Sessions!T10),0) -> 0 | AS8: =IFERROR(N(Sessions!V10),0) -> 0 | AT8: =IFERROR(N(Sessions!X10),0) -> 0 | AU8: =IFERROR(N(Sessions!AA10),0) -> 0 | AV8: =IFERROR(N(Sessions!AC10),0) -> 0 | AW8: =IFERROR(N(Sessions!AE10),0) -> 0 | AX8: =IFERROR(N(Sessions!AH10),0) -> 0 | AY8: =IFERROR(N(Sessions!AJ10),0) -> 0 | AZ8: =IFERROR(N(Sessions!AL10),0) -> 0 | BA8: =IFERROR(N(Sessions!AO10),0) -> 0 | BB8: =IFERROR(N(Sessions!AQ10),0) -> 0 | BC8: =IFERROR(N(Sessions!AS10),0) -> 0 | BD8: =IFERROR(N(Sessions!AV10),0) -> 0 | BE8: =IFERROR(N(Sessions!AX10),0) -> 0 | BF8: =IFERROR(N(Sessions!AZ10),0) -> 0 | BG8: =IFERROR(N(Sessions!BC10),0) -> 0 | BH8: =IFERROR(N(Sessions!BE10),0) -> 0 | BI8: =IFERROR(N(Sessions!BG10),0) -> 0 | BJ8: =IFERROR(N(Sessions!BJ10),0) -> 0 | BK8: =IFERROR(N(Sessions!BL10),0) -> 0 | BL8: =IFERROR(N(Sessions!BN10),0) -> 0 | BM8: =IFERROR(N(Sessions!BQ10),0) -> 0 | BN8: =IFERROR(N(Sessions!BS10),0) -> 0 | BO8: =IFERROR(N(Sessions!BU10),0) -> 0 | BP8: =IFERROR(N(Sessions!BX10),0) -> 0 | BQ8: =IFERROR(N(Sessions!BZ10),0) -> 0 | BR8: =IFERROR(N(Sessions!CB10),0) -> 0 | BS8: =IFERROR(N(Sessions!CE10),0) -> 0 | BT8: =IFERROR(N(Sessions!CG10),0) -> 0 | BU8: =IFERROR(N(Sessions!CI10),0) -> 0 | BV8: =IF(B8=0,0,IFERROR(N(Sessions!D10),0)) -> 0 | BW8: =IF(C8=0,0,IFERROR(N(Sessions!D10),0)) -> 0 | BX8: =IF(D8=0,0,IFERROR(N(Sessions!D10),0)) -> 0 | BY8: =IF(E8=0,0,IFERROR(N(Sessions!K10),0)) -> 0 | BZ8: =IF(F8=0,0,IFERROR(N(Sessions!K10),0)) -> 0 | CA8: =IF(G8=0,0,IFERROR(N(Sessions!K10),0)) -> 0 | CB8: =IF(H8=0,0,IFERROR(N(Sessions!R10),0)) -> 0 | CC8: =IF(I8=0,0,IFERROR(N(Sessions!R10),0)) -> 0 | CD8: =IF(J8=0,0,IFERROR(N(Sessions!R10),0)) -> 0 | CE8: =IF(K8=0,0,IFERROR(N(Sessions!Y10),0)) -> 0 | CF8: =IF(L8=0,0,IFERROR(N(Sessions!Y10),0)) -> 0 | CG8: =IF(M8=0,0,IFERROR(N(Sessions!Y10),0)) -> 0 | CH8: =IF(N8=0,0,IFERROR(N(Sessions!AF10),0)) -> 0 | CI8: =IF(O8=0,0,IFERROR(N(Sessions!AF10),0)) -> 0 | CJ8: =IF(P8=0,0,IFERROR(N(Sessions!AF10),0)) -> 0 | CK8: =IF(Q8=0,0,IFERROR(N(Sessions!AM10),0)) -> 0 | CL8: =IF(R8=0,0,IFERROR(N(Sessions!AM10),0)) -> 0 | CM8: =IF(S8=0,0,IFERROR(N(Sessions!AM10),0)) -> 0 | CN8: =IF(T8=0,0,IFERROR(N(Sessions!AT10),0)) -> 0 | CO8: =IF(U8=0,0,IFERROR(N(Sessions!AT10),0)) -> 0 | CP8: =IF(V8=0,0,IFERROR(N(Sessions!AT10),0)) -> 0 | CQ8: =IF(W8=0,0,IFERROR(N(Sessions!BA10),0)) -> 0 | CR8: =IF(X8=0,0,IFERROR(N(Sessions!BA10),0)) -> 0 | CS8: =IF(Y8=0,0,IFERROR(N(Sessions!BA10),0)) -> 0 | CT8: =IF(Z8=0,0,IFERROR(N(Sessions!BH10),0)) -> 0 | CU8: =IF(AA8=0,0,IFERROR(N(Sessions!BH10),0)) -> 0 | CV8: =IF(AB8=0,0,IFERROR(N(Sessions!BH10),0)) -> 0 | CW8: =IF(AC8=0,0,IFERROR(N(Sessions!BO10),0)) -> 0 | CX8: =IF(AD8=0,0,IFERROR(N(Sessions!BO10),0)) -> 0 | CY8: =IF(AE8=0,0,IFERROR(N(Sessions!BO10),0)) -> 0 | CZ8: =IF(AF8=0,0,IFERROR(N(Sessions!BV10),0)) -> 0 | DA8: =IF(AG8=0,0,IFERROR(N(Sessions!BV10),0)) -> 0 | DB8: =IF(AH8=0,0,IFERROR(N(Sessions!BV10),0)) -> 0 | DC8: =IF(AI8=0,0,IFERROR(N(Sessions!CC10),0)) -> 0 | DD8: =IF(AJ8=0,0,IFERROR(N(Sessions!CC10),0)) -> 0 | DE8: =IF(AK8=0,0,IFERROR(N(Sessions!CC10),0)) -> 0 | DF8: =B8*100000+AL8 -> 500000 | DG8: =C8*100000+AM8 -> 0 | DH8: =D8*100000+AN8 -> 0 | DI8: =E8*100000+AO8 -> 0 | DJ8: =F8*100000+AP8 -> 0 | DK8: =G8*100000+AQ8 -> 0 | DL8: =H8*100000+AR8 -> 0 | DM8: =I8*100000+AS8 -> 0 | ... EO8: =AK8*100000+BU8 -> 0
A9: =Sessions!B11 -> Single Leg Lying Hamstring Curl | B9: =IFERROR(N(Sessions!E11),0) -> 15 | C9: =IFERROR(N(Sessions!G11),0) -> 0 | D9: =IFERROR(N(Sessions!I11),0) -> 0 | E9: =IFERROR(N(Sessions!L11),0) -> 0 | F9: =IFERROR(N(Sessions!N11),0) -> 0 | G9: =IFERROR(N(Sessions!P11),0) -> 0 | H9: =IFERROR(N(Sessions!S11),0) -> 0 | I9: =IFERROR(N(Sessions!U11),0) -> 0 | J9: =IFERROR(N(Sessions!W11),0) -> 0 | K9: =IFERROR(N(Sessions!Z11),0) -> 0 | L9: =IFERROR(N(Sessions!AB11),0) -> 0 | M9: =IFERROR(N(Sessions!AD11),0) -> 0 | N9: =IFERROR(N(Sessions!AG11),0) -> 0 | O9: =IFERROR(N(Sessions!AI11),0) -> 0 | P9: =IFERROR(N(Sessions!AK11),0) -> 0 | Q9: =IFERROR(N(Sessions!AN11),0) -> 0 | R9: =IFERROR(N(Sessions!AP11),0) -> 0 | S9: =IFERROR(N(Sessions!AR11),0) -> 0 | T9: =IFERROR(N(Sessions!AU11),0) -> 0 | U9: =IFERROR(N(Sessions!AW11),0) -> 0 | V9: =IFERROR(N(Sessions!AY11),0) -> 0 | W9: =IFERROR(N(Sessions!BB11),0) -> 0 | X9: =IFERROR(N(Sessions!BD11),0) -> 0 | Y9: =IFERROR(N(Sessions!BF11),0) -> 0 | Z9: =IFERROR(N(Sessions!BI11),0) -> 0 | AA9: =IFERROR(N(Sessions!BK11),0) -> 0 | AB9: =IFERROR(N(Sessions!BM11),0) -> 0 | AC9: =IFERROR(N(Sessions!BP11),0) -> 0 | AD9: =IFERROR(N(Sessions!BR11),0) -> 0 | AE9: =IFERROR(N(Sessions!BT11),0) -> 0 | AF9: =IFERROR(N(Sessions!BW11),0) -> 0 | AG9: =IFERROR(N(Sessions!BY11),0) -> 0 | AH9: =IFERROR(N(Sessions!CA11),0) -> 0 | AI9: =IFERROR(N(Sessions!CD11),0) -> 0 | AJ9: =IFERROR(N(Sessions!CF11),0) -> 0 | AK9: =IFERROR(N(Sessions!CH11),0) -> 0 | AL9: =IFERROR(N(Sessions!F11),0) -> 0 | AM9: =IFERROR(N(Sessions!H11),0) -> 0 | AN9: =IFERROR(N(Sessions!J11),0) -> 0 | AO9: =IFERROR(N(Sessions!M11),0) -> 0 | AP9: =IFERROR(N(Sessions!O11),0) -> 0 | AQ9: =IFERROR(N(Sessions!Q11),0) -> 0 | AR9: =IFERROR(N(Sessions!T11),0) -> 0 | AS9: =IFERROR(N(Sessions!V11),0) -> 0 | AT9: =IFERROR(N(Sessions!X11),0) -> 0 | AU9: =IFERROR(N(Sessions!AA11),0) -> 0 | AV9: =IFERROR(N(Sessions!AC11),0) -> 0 | AW9: =IFERROR(N(Sessions!AE11),0) -> 0 | AX9: =IFERROR(N(Sessions!AH11),0) -> 0 | AY9: =IFERROR(N(Sessions!AJ11),0) -> 0 | AZ9: =IFERROR(N(Sessions!AL11),0) -> 0 | BA9: =IFERROR(N(Sessions!AO11),0) -> 0 | BB9: =IFERROR(N(Sessions!AQ11),0) -> 0 | BC9: =IFERROR(N(Sessions!AS11),0) -> 0 | BD9: =IFERROR(N(Sessions!AV11),0) -> 0 | BE9: =IFERROR(N(Sessions!AX11),0) -> 0 | BF9: =IFERROR(N(Sessions!AZ11),0) -> 0 | BG9: =IFERROR(N(Sessions!BC11),0) -> 0 | BH9: =IFERROR(N(Sessions!BE11),0) -> 0 | BI9: =IFERROR(N(Sessions!BG11),0) -> 0 | BJ9: =IFERROR(N(Sessions!BJ11),0) -> 0 | BK9: =IFERROR(N(Sessions!BL11),0) -> 0 | BL9: =IFERROR(N(Sessions!BN11),0) -> 0 | BM9: =IFERROR(N(Sessions!BQ11),0) -> 0 | BN9: =IFERROR(N(Sessions!BS11),0) -> 0 | BO9: =IFERROR(N(Sessions!BU11),0) -> 0 | BP9: =IFERROR(N(Sessions!BX11),0) -> 0 | BQ9: =IFERROR(N(Sessions!BZ11),0) -> 0 | BR9: =IFERROR(N(Sessions!CB11),0) -> 0 | BS9: =IFERROR(N(Sessions!CE11),0) -> 0 | BT9: =IFERROR(N(Sessions!CG11),0) -> 0 | BU9: =IFERROR(N(Sessions!CI11),0) -> 0 | BV9: =IF(B9=0,0,IFERROR(N(Sessions!D11),0)) -> 0 | BW9: =IF(C9=0,0,IFERROR(N(Sessions!D11),0)) -> 0 | BX9: =IF(D9=0,0,IFERROR(N(Sessions!D11),0)) -> 0 | BY9: =IF(E9=0,0,IFERROR(N(Sessions!K11),0)) -> 0 | BZ9: =IF(F9=0,0,IFERROR(N(Sessions!K11),0)) -> 0 | CA9: =IF(G9=0,0,IFERROR(N(Sessions!K11),0)) -> 0 | CB9: =IF(H9=0,0,IFERROR(N(Sessions!R11),0)) -> 0 | CC9: =IF(I9=0,0,IFERROR(N(Sessions!R11),0)) -> 0 | CD9: =IF(J9=0,0,IFERROR(N(Sessions!R11),0)) -> 0 | CE9: =IF(K9=0,0,IFERROR(N(Sessions!Y11),0)) -> 0 | CF9: =IF(L9=0,0,IFERROR(N(Sessions!Y11),0)) -> 0 | CG9: =IF(M9=0,0,IFERROR(N(Sessions!Y11),0)) -> 0 | CH9: =IF(N9=0,0,IFERROR(N(Sessions!AF11),0)) -> 0 | CI9: =IF(O9=0,0,IFERROR(N(Sessions!AF11),0)) -> 0 | CJ9: =IF(P9=0,0,IFERROR(N(Sessions!AF11),0)) -> 0 | CK9: =IF(Q9=0,0,IFERROR(N(Sessions!AM11),0)) -> 0 | CL9: =IF(R9=0,0,IFERROR(N(Sessions!AM11),0)) -> 0 | CM9: =IF(S9=0,0,IFERROR(N(Sessions!AM11),0)) -> 0 | CN9: =IF(T9=0,0,IFERROR(N(Sessions!AT11),0)) -> 0 | CO9: =IF(U9=0,0,IFERROR(N(Sessions!AT11),0)) -> 0 | CP9: =IF(V9=0,0,IFERROR(N(Sessions!AT11),0)) -> 0 | CQ9: =IF(W9=0,0,IFERROR(N(Sessions!BA11),0)) -> 0 | CR9: =IF(X9=0,0,IFERROR(N(Sessions!BA11),0)) -> 0 | CS9: =IF(Y9=0,0,IFERROR(N(Sessions!BA11),0)) -> 0 | CT9: =IF(Z9=0,0,IFERROR(N(Sessions!BH11),0)) -> 0 | CU9: =IF(AA9=0,0,IFERROR(N(Sessions!BH11),0)) -> 0 | CV9: =IF(AB9=0,0,IFERROR(N(Sessions!BH11),0)) -> 0 | CW9: =IF(AC9=0,0,IFERROR(N(Sessions!BO11),0)) -> 0 | CX9: =IF(AD9=0,0,IFERROR(N(Sessions!BO11),0)) -> 0 | CY9: =IF(AE9=0,0,IFERROR(N(Sessions!BO11),0)) -> 0 | CZ9: =IF(AF9=0,0,IFERROR(N(Sessions!BV11),0)) -> 0 | DA9: =IF(AG9=0,0,IFERROR(N(Sessions!BV11),0)) -> 0 | DB9: =IF(AH9=0,0,IFERROR(N(Sessions!BV11),0)) -> 0 | DC9: =IF(AI9=0,0,IFERROR(N(Sessions!CC11),0)) -> 0 | DD9: =IF(AJ9=0,0,IFERROR(N(Sessions!CC11),0)) -> 0 | DE9: =IF(AK9=0,0,IFERROR(N(Sessions!CC11),0)) -> 0 | DF9: =B9*100000+AL9 -> 1500000 | DG9: =C9*100000+AM9 -> 0 | DH9: =D9*100000+AN9 -> 0 | DI9: =E9*100000+AO9 -> 0 | DJ9: =F9*100000+AP9 -> 0 | DK9: =G9*100000+AQ9 -> 0 | DL9: =H9*100000+AR9 -> 0 | DM9: =I9*100000+AS9 -> 0 | ... EO9: =AK9*100000+BU9 -> 0
